Workbook
Name a: 'WELL TESTS'!$K$3:$K$13
Name ACTUALINJ: 'WATER FLOOD WELLS'!$I$5:$I$76
Name ACTUALTODAY: REPORT!$H$8:$H$18
Name ACTUALYESTERDAY: REPORT!$G$8:$G$18
Name API_RANGE: TEMPERATURE!$C$2:$BA$2
Name asd: 'WELL TESTS'!$C$3:$C$13
Name asdsad: 'WELL TESTS'!$C$3:$C$13
Name AUTOFILL01: 'WELL DATA'!$CW$4:$DS$147
Name AUTOFILL02: 'WATER FLOOD WELLS'!$AY$4:$BH$76
Name AUTOFILL03: 'WELL TESTS'!$AO$3:$BG$13
Name AUTOFILL04: 'WELL TESTS'!$L$3:$L$13
Name AUTOFILL05: 'WELL TESTS'!$N$3:$N$13
Name AUTOFILL06: 'DFL SHOTS'!$Z$3:$AJ$21
Name AUTOFILL07: 'DFL SHOTS'!$J$3:$J$21
Name AUTOFILL08: 'WELL DATA'!$G$4:$G$147
Name AUTOFILL09: 'WELL DATA'!$AN$4:$AN$147
Name AUTOFILL10: 'WATER FLOOD WELLS'!$O$3:$O$7
Name AUTOFILL11: 'WELL DATA'!$AI$4:$AI$147
Name AUTOFILL12: PROCESS!$AK$3:$AU$29
Name AUTOFILL12: 'EQUIPMENT DATA'!$AI$3:$AS$25
Name aw: 'WELL TESTS'!$M$3:$M$13
Name BFPD: 'WELL DATA'!$AK$4:$AK$147
Name BOPD: 'WELL DATA'!$AN:$AN
Name BSSTATUS: TANKS!$C$3:$C$6
Name BSW: 'WELL DATA'!$AM$4:$AM$147
Name CALC01: 'WELL DATA'!$CW$4:$DS$4
Name CALC02: 'WATER FLOOD WELLS'!$AY$4:$BH$4
Name CALC03: 'WELL TESTS'!#REF!
Name CALC04: 'WELL TESTS'!#REF!
Name CALC05: 'WELL TESTS'!#REF!
Name CALC06: 'DFL SHOTS'!$Z$3:$AJ$3
Name CALC07: 'LAB DATA'!$I$4
Name CALC08: 'WELL DATA'!$G$4
Name CALC09: 'WELL DATA'!$AN$4
Name CALC10: 'WATER FLOOD WELLS'!$O$3
Name CALC11: 'WELL DATA'!$AI$4
Name CALC12: PROCESS!$AK$3:$AU$3
Name CALC12: 'EQUIPMENT DATA'!$AI$3:$AS$3
Name CASING_STATUS: ADMIN!$P$49:$P$50
Name CHOKE: ADMIN!$N$3:$N$35
Name CLEAR013: 'DATA INPUT'!$E$3:$E$16
Name CLEARPF: REPORT!$N$13
Name CLEARRANGE01: REPORT!$B$61:$L$92
Name CLEARRANGE02: 'WELL TESTS'!$B$3:$K$13,'WELL TESTS'!$M$3:$M$13,'WELL TESTS'!$O$3:$V$13,'WELL TESTS'!$B$16:$K$24,'WELL TESTS'!$M$16:$M$24,'WELL TESTS'!$O$16:$W$24
Name CLEARRANGE03: 'WELL DATA'!$AP$147:$AP$147
Name CLEARRANGE04: 'DATA INPUT'!#REF!
Name CLEARRANGE04: 'DATA INPUT'!#REF!
Name CLEARRANGE04: 'DATA INPUT'!#REF!
Name CLEARRANGE05: 'LAB DATA'!$B$5:$J$15
Name CLEARRANGE05: 'DFL SHOTS'!$B$4:$M$21
Name CLEARRANGE06: PROCESS!$C$3:$J$29
Name CLEARRANGE06: 'EQUIPMENT DATA'!$D$3:$I$25
Name CLEARRANGE07: 'DATA INPUT'!$G$20:$I$61
Name CLEARRANGE08: 'DATA INPUT'!$E$72
Name CLEARRANGE09: PROCESS!$C$4:$J$29
Name CLEARRANGE09: 'EQUIPMENT DATA'!$D$4:$I$25
Name CLOSINGSTK: REPORT!$C$26:$E$26
Name COMMENT: REPORT!$B$92:$K$95
Name COPYRANGE01: #REF!
Name COPYRANGE02: #REF!

Sheet REPORT
B3: ="VERSION "&VERSION -> VERSION 1 | D3: KHALDA PETROLEUM COMPANY | J3: =+REPDATE -> 46285 | AU3: AVOCET TAG | AV3: DATE | AW3: PLANT | AX3: TYPE | AY3: METER NAME | AZ3: MT | BA3: LIQUID | BB3: Gas | CC3: Click this button to save the file to the X: drive (as FILE1,xls)
AU4: KHALDA_METER | AV4: =REPORTDATE-1 -> 46284 | AW4: 9RAZAAK OP | AX4: B | AY4: RZK OIL | AZ4: L | BA4: =M7 -> 5561.4687
D5: Production Day Ending @ 0600 Hours | AU5: KHALDA_METER | AV5: =REPORTDATE-1 -> 46284 | AW5: 9RAZAAK OP | AX5: B | AY5: RZK INJECTION | AZ5: L | BA5: ='WATER FLOOD WELLS'!I77 -> 49854.492
B6: RAZZAK PRODUCTION SUMMARY | D6: =REPDATE -> 46285 | M6: Production BBLs | N6: Actual BBLs | AU6: KHALDA_METER | AV6: =REPORTDATE-1 -> 46284 | AW6: 9AKIK-NE FLARE | AX6: B | AY6: AKIK-NE FLARE | AZ6: O | BB6: =+'WELL DATA'!AL18 -> 1.991
B7: FIELD NAME | C7: FLOWING WELLS | D7: NET PROD TODAY | E7: NET PROD YESTERDAY | F7: DELTA STB | G7: ACTUAL Yesterday | H7: Actual TODAY | I7: DELTA ACTUAL | K7: RZK PRODUCTION | M7: =H27 -> 5561.4687 | N7: ='DATA INPUT'!G10 -> 5567 | O7: =N7/M7 -> 1.0009946 | AU7: KHALDA_METER | AV7: =REPORTDATE-1 -> 46284 | AW7: 9NORTH RAS QATTARA | AX7: B | AY7: NORTH RAS QATTARA WATER INJ | AZ7: L | BA7: ='WATER FLOOD WELLS'!I78 -> 7680
B8: MAIN RAZZAK | C8: =IFERROR(IF(TDYPROD=0,0,COUNTIF(FIELD,"MAIN")),"") -> 25 | D8: =IFERROR(SUMIF(FIELD,"MAIN",EST_PROD)*OIL_PROFAC,"") -> 1704.9293 | E8: 1673.7059 | F8: =IF(D8="","",D8-E8) -> 31.223369 | G8: 1673.6101 | H8: =D8*RZKActual_Ratio -> 1706.625 | I8: =IF(H8="","",H8-G8) -> 33.014901 | K8: NRQ OIL PRODUCTION | M8: ='DATA INPUT'!E12 -> 494 | N8: ='DATA INPUT'!G12 -> 494 | AU8: KHALDA_METER | AV8: =REPORTDATE-1 -> 46284 | AW8: 9NWRZK FLARE | AX8: B | AY8: NWRZK FLARE | AZ8: O | BB8: =+'WELL DATA'!AL20+'WELL DATA'!AL22 -> 0
B9: EAST RAZZAK | C9: =IFERROR(IF(TDYPROD=0,0,COUNTIF(FIELD,"EAST")),"") -> 8 | D9: =IFERROR(SUMIF(FIELD,"EAST",EST_PROD)*OIL_PROFAC,"") -> 765.47758 | E9: 774.99049 | F9: =IF(D9="","",D9-E9) -> -9.5129158 | G9: 774.94612 | H9: =D9*RZKActual_Ratio -> 766.23891 | I9: =IF(H9="","",H9-G9) -> -8.7072081 | K9: NWRZK OIL PRODUCTION | M9: ='DATA INPUT'!E11 -> 122 | N9: ='DATA INPUT'!G11 -> 122 | AU9: KHALDA_METER | AV9: =REPORTDATE-1 -> 46284 | AW9: 9RZK Flare | AX9: B | AY9: RZK Flare | AZ9: O | BB9: =+L33 -> 0.79
B10: NORTH RAZZAK | C10: =IFERROR(IF(TDYPROD=0,0,COUNTIF(FIELD,"NORTH")),"") -> 9 | D10: =IFERROR(SUMIF(FIELD,"NORTH",EST_PROD)*OIL_PROFAC,"") -> 561.45326 | E10: 551.75737 | F10: =IF(D10="","",D10-E10) -> 9.6958946 | G10: 551.72577 | H10: =D10*RZKActual_Ratio -> 562.01167 | I10: =IF(H10="","",H10-G10) -> 10.285901 | K10: AKIK OIL PRODUCTION | M10: ='DATA INPUT'!E13 -> 243 | N10: ='DATA INPUT'!G13 -> 243
B11: WEST RAZZAK | C11: =IFERROR(IF(TDYPROD=0,0,COUNTIF(FIELD,"WEST")),"") -> 36 | D11: =IFERROR(SUMIF(FIELD,"WEST",EST_PROD)*OIL_PROFAC,"") -> 2529.6085 | E11: 2572.8654 | F11: =IF(D11="","",D11-E11) -> -43.256824 | G11: 2572.718 | H11: =D11*RZKActual_Ratio -> 2532.1245 | I11: =IF(H11="","",H11-G11) -> -40.593593 | K11: RAFIKI OIL PRODUCTION | M11: ='DATA INPUT'!E14 -> 118 | N11: ='DATA INPUT'!G14 -> 118
B12: TOTALS | C12: =IFERROR(SUM(C8:C11),"") -> 78 | D12: =IFERROR(SUM(D8:D11),"") -> 5561.4687 | E12: 5573.3191 | F12: =SUM(F8:F11) -> -11.850476 | G12: 5573 | H12: =IFERROR(SUM(H8:H11),"") -> 5567 | I12: =IF(H12="","",H12-G12) -> -6 | K12: NERZK OIL PRODUCTION | M12: ='DATA INPUT'!E15 -> 135 | N12: ='DATA INPUT'!G15 -> 135
B13: NWRZK | C13: =IFERROR(IF(TDYPROD=0,0,COUNTIF(FIELD,"NWRZK")),"") -> 1 | D13: =+'DATA INPUT'!E11 -> 122 | E13: 121 | F13: =IF(D13="","",D13-E13) -> 1 | G13: 121 | H13: =+N9 -> 122 | I13: =IF(H13="","",H13-G13) -> 1 | K13: FIELD | L13: ACTUAL | M13: REQUIRED | N13: DELTA
B14: NORTH RAS QATTARA | C14: =IFERROR(IF(TDYPROD=0,0,COUNTIF(FIELD,"NRQ")),"") -> 14 | D14: ='DATA INPUT'!E12 -> 494 | E14: 491 | F14: =IF(D14="","",D14-E14) -> 3 | G14: 491 | H14: =N8 -> 494 | I14: =IF(H14="","",H14-G14) -> 3 | K14: MRZK | L14: ='WATER FLOOD WELLS'!$I$99 -> 17523.292 | M14: ='WATER FLOOD WELLS'!$J$99 -> 19000 | N14: ='WATER FLOOD WELLS'!$K$99 -> -1476.7083
B15: AKIK-NE | C15: =IFERROR(IF(TDYPROD=0,0,COUNTIF(FIELD,"AKIK-NE")),"")+IFERROR(IF(TDYPROD=0,0,COUNTIF(FIELD,"Tanz")),"") -> 1 | D15: ='DATA INPUT'!E13 -> 243 | E15: 251 | F15: =IF(D15="","",D15-E15) -> -8 | G15: 251 | H15: =N10 -> 243 | I15: =IF(H15="","",H15-G15) -> -8 | K15: WRZK | L15: ='WATER FLOOD WELLS'!$I$100 -> 26151.2 | M15: ='WATER FLOOD WELLS'!$J$100 -> 28050 | N15: ='WATER FLOOD WELLS'!$K$100 -> -1898.8
B16: RAFIKI | C16: =IFERROR(IF(TDYPROD=0,0,COUNTIF(FIELD,"RAFIKI")),"") -> 1 | D16: ='DATA INPUT'!E14 -> 118 | E16: 119 | F16: =IF(D16="","",D16-E16) -> -1 | G16: 119 | H16: =N11 -> 118 | I16: =IF(H16="","",H16-G16) -> -1 | K16: ERZK | L16: ='WATER FLOOD WELLS'!$I$101 -> 6180 | M16: ='WATER FLOOD WELLS'!$J$101 -> 6700 | N16: ='WATER FLOOD WELLS'!$K$101 -> -520
B17: NERZK | C17: =IFERROR(IF(TDYPROD=0,0,COUNTIF(FIELD,"NERZK A")),"") -> 1 | D17: ='DATA INPUT'!E15 -> 135 | E17: 135 | F17: =IF(D17="","",D17-E17) -> 0 | G17: 135 | H17: =N12 -> 135 | I17: =IF(H17="","",H17-G17) -> 0 | K17: NRQ | L17: ='WATER FLOOD WELLS'!$I$102 -> 7680 | M17: ='WATER FLOOD WELLS'!$J$102 -> 10600 | N17: ='WATER FLOOD WELLS'!$K$102 -> -2920
B18: RAZZAK/NRQ/AKIK/RAFIKI/NWRZK TOTAL | C18: =SUM(C12:C17) -> 96 | D18: =SUM(D12:D17) -> 6673.4687 | E18: =SUM(E12:E17) -> 6690.3191 | F18: =IF(D18="","",D18-E18) -> -16.850476 | G18: 6690 | H18: =SUM(H12:H17) -> 6679 | I18: =IF(H18="","",H18-G18) -> -11 | K18: TOTAL | L18: =SUM(L14:L17) -> 57534.492 | M18: =SUM(M14:M17) -> 64350 | N18: =SUM(N14:N17) -> -6815.5083
B20: TANK SUMMARY | I20: TOP THREE DOWNTIME CAUSES | L20: bbl | AU20: RECORD | AV20: DATE | AW20: Tank Name | AX20: Tank Status | AY20: Open Stock (STB) | AZ20: Closing Stock (STB) | BA20: API (°) | BB20: BS&W (%) | BC20: SC (PTB) | BD20: Pour Point (°F) | BE20: Temperature (°F) | BF20: Shipment (Tickets) | BG20: Free Water Volume BBLs
B21: ITEM | C21: TANK 201 | E21: TANK 202 | G21: TOTALS | H21: TOTALS WITHOUT EPF'S | I21: =IF(L21="","",VLOOKUP(REPORT!L21,ADMIN!B3:G121,6,FALSE)) -> Generator (Planned) | L21: =IF(M7=0,0,MAX(ADMIN!B3:G121)) -> 48.533168
B22: Tank Status | C22: Shipping | E22: Production | I22: =IF(L22=0,"",VLOOKUP(REPORT!L22,ADMIN!B3:G121,6,FALSE)) -> Flowline Failure | L22: =IF(M7=0,0,LARGE(ADMIN!B3:G121,2)) -> 13.30325 | AU22: KPC_TANKSLVL | AV22: =REPORTDATE-1 -> 46284 | AW22: TANK 201 | AX22: =C22 -> Shipping | AY22: =C23 -> 8731.1846 | AZ22: =C26 -> 14353.68 | BA22: =C29 -> 33.1 | BB22: =C30 -> 0 | BC22: =C31 -> 0 | BE22: =C28 -> 110
B23: Opening Stock | C23: =IFERROR(TANKS!E3,"") -> 8731.1846 | E23: =IFERROR(TANKS!E5,"") -> 14100.068 | G23: =SUM(OPENINGSTK) -> 22831.253 | H23: =SUM(OPENINGSTK) -> 22831.253 | I23: =IF(L23=0,"",VLOOKUP(REPORT!L23,ADMIN!B3:G121,6,FALSE)) -> Generator (Unplanned) | L23: =IF(M7=0,0,LARGE(ADMIN!B3:G121,3)) -> 12.333708 | AU23: KPC_TANKSLVL | AV23: =REPORTDATE-1 -> 46284 | AW23: TANK 202 | AX23: =E22 -> Production | AY23: =E23 -> 14100.068 | AZ23: =E26 -> 8550.0415 | BA23: =E29 -> 33.1 | BB23: =E30 -> 0 | BC23: =E31 -> 0 | BE23: =E28 -> 62 | BF23: m
B24: Net Pumped | C24: =IFERROR(TANKS!M3,"") -> 0 | E24: =IFERROR(TANKS!M5,"") -> 6677 | G24: =SUM(SHIPPED) -> 6677 | H24: =SUM(SHIPPED)-('DATA INPUT'!E5+'DATA INPUT'!E6+'DATA INPUT'!E7+'DATA INPUT'!E8+'DATA INPUT'!E9) -> 5489 | I24: LIQUIDS INVENTORY
B25: Water Drained | C25: =IFERROR(TANKS!N3,"") -> 0 | E25: =IFERROR(TANKS!N5,"") -> 65 | G25: =SUM(WATERDRAIN) -> 65 | H25: =SUM(WATERDRAIN) -> 65 | I25: Oil Stock - Today | K25: =IFERROR(G26,"") -> 22903.721 | L25: BBLS
B26: Closing Stock | C26: =IFERROR(TANKS!E4,"") -> 14353.68 | E26: =IFERROR(TANKS!E6,"") -> 8550.0415 | G26: =SUM(CLOSINGSTK) -> 22903.721 | H26: =SUM(CLOSINGSTK) -> 22903.721 | I26: Oil Stock - Yesterday | K26: =G23 -> 22831.253 | L26: BBLS
E27: PRODUCTION | G27: =IFERROR(IF((G26+G24-G23)<0,G25*-1,(G26+G24-G23)),0) -> 6749.4687 | H27: =IFERROR(IF((H26+H24-H23)<0,H25*-1,(H26+H24-H23)),0) -> 5561.4687 | I27: TOTAL SHIPPED OIL | K27: =TOTPUMPED -> 6677 | L27: BBL
B28: Temperature (°F) | C28: ='DATA INPUT'!E22 -> 110 | E28: ='DATA INPUT'!E31 -> 62 | I28: FLOW STATUS | J28: WELLS | K28: STATUS | L28: WELLS
B29: API gravity (DEG) | C29: ='DATA INPUT'!E24 -> 33.1 | E29: ='DATA INPUT'!E32 -> 33.1 | I29: NF | J29: =COUNTIF(STATUS,"NF") -> 2 | K29: GL | L29: =COUNTIF(STATUS,"GL") -> 0
B30: BS&W (%) | C30: ='DATA INPUT'!E25 -> 0 | E30: ='DATA INPUT'!E33 -> 0 | I30: ESP | J30: =COUNTIF(STATUS,"ESP") -> 70 | K30: WIW | L30: =COUNTIF(INJSTAUS,"INJ") -> 50
B31: Salt (PTB) | C31: ='DATA INPUT'!E26 -> 0 | E31: ='DATA INPUT'!E34 -> 0 | I31: SRP | J31: =COUNTIF(STATUS,"SRP") -> 20 | K31: WSW | L31: =COUNTIF(WSWSTAUS,"ESP") -> 10 | AU31: RECORD | AV31: DATE | AW31: Tank Name | AX31: Open Stock (STB) | AY31: Closing Stock (STB) | AZ31: Shipment (Tickets) | BA31: T_DIS_TYPE | BB31: DESTENATION
I32: PCP | J32: =COUNTIF(STATUS,"PCP") -> 4 | K32: Flared Gas, MMSCFD
I33: TOTAL WELLS | J33: =SUM(J29:J32)+L29 -> 96 | K33: RZK Amount, MMSCFD | L33: 0.79
B34: DEFERRED PRODUCTION (Due to Operational Activities) | K34: NRQ Amount, MMSCFD | AU34: KPC_TANKSTCTK
B35: WELL NAME | C35: DT | D35: COMMENTS | L35: BBLS
B36: NRZK-(02, 21ST), WRZK-167 | C36: 0 | D36: Back online 24 Hrs after Generator (Planned) | L36: 27
B37: MRZK-(76,07,186), NRZK-11 | C37: 2 | D37: Generator (Planned) | L37: -32
B38: MRZK-(97,75), NRZK-18ST, WRZK-(192,193,194,148,169) | C38: 1 | D38: Generator (Planned) | L38: -11
B39: WRZK-190 | C39: 7 | D39: Generator (unplanned) & Adjust valve lash and replaced corroded section at mini manifold. | L39: -12
B40: WRZK-(55,119) | C40: 2 | D40: Replaced corroded section at mini manifold. | L40: -13
B41: WRZK-41 | C41: 2 | D41: Generator (Planned) & Replaced corroded section at mini manifold. | L41: -6
B42: MRZK-29 | C42: 0 | D42: Opened after PBU | L42: 58
B45: RZK PROD. WELLS | D45: Wells & Lines Performance. ERZK-163: Updated test (-6 BO) | L45: =IF($D$12=0,"",($F$12-SUM(L36:L44))) -> -22.850476
...

Sheet WELL TESTS
B1: WELL TESTS | AT1: =COUNTIF(DATATAG,"KHALDA_WELLTEST1") -> 3 | AV1: ="AO3"&":"&"BF"&COUNTIF(DATATAG,"<>0")+5 -> AO3:BF8
B2: TEST FACILITY | C2: WELL NAME | D2: ZONE | E2: STATUS | F2: CHOKE 64" | G2: WHP PSI | H2: WHT °F | I2: SEP PSI | J2: BFPD STB | K2: BS&W % | L2: BOPD STB | M2: GAS MMSCF | N2: GOR scf/bbl | O2: HRS ON TEST | P2: DFL | Q2: NLAP | R2: PIP | S2: FREQUENCY | T2: CSG PSI | U2: CSG STATUS | V2: CL, PPM | W2: COMMENTS | X2: TYPE | AO2: RECORD | AP2: DATE | AQ2: WELL | AR2: WELL | AS2: HOURS | AT2: TYPE | AU2: BFPD | AV2: GAS | AW2: CHOKE | AX2: WHP | AY2: WHT | AZ2: SEP | BA2: DFL | BB2: NLAP | BC2: BSW | BD2: PIP | BE2: FREQUENCY | BF2: LIQ TYPE | BG2: GAS LIFT | BH2: CL, PPM
B3: MTU-07 | C3: MRZK-76 | D3: BAH | E3: ESP | F3: SPOOL | G3: 100 | H3: 152 | I3: 88 | J3: 1180 | K3: 91.94 | L3: =IF(WELLNAME="","",(FLUIDTOTAL*(1-(WC/100)))) -> 95.108 | N3: =IF(ISNUMBER(M3),(M3*10^6)/L3,"") | O3: 9.5 | R3: 881 | S3: 59 | T3: N/A | U3: OP/P | V3: 64000 | W3: W.C F/ (MTU 91.94 %, LAB 91.9 %, WHS 92 %). AMP= 26.5-26.7, HZ= 59, H2S= 0 PPM, CO2= 1 %, API= 29.1, CL= 64 KPPM, MF= 0.94, PIP= 881 PSI. | AN3: 9 | AO3: =IF(C2="",0,"KHALDA_WELLTEST1") -> KHALDA_WELLTEST1 | AP3: =IF(AO3="","",REPORTDATE-1) -> 46284 | AQ3: =UPPER(IF(AO3="","",$AN$3&C3)) -> 9MRZK-76 | AR3: =UPPER(IF(AO3="","",$AN$3&C3)) -> 9MRZK-76 | AS3: =IF(AO3="","",O3) -> 9.5 | AT3: =IF(AO3=0,"",X3) -> 0 | AU3: =IF(AO3="","",J3) -> 1180 | AV3: =IF(AO3="","",M3*1000) -> 0 | AW3: =IF(AO3="","",F3) -> SPOOL | AX3: =IF(AO3="","",G3) -> 100 | AY3: =IF(AO3="","",H3) -> 152 | AZ3: =IF(AO3="","",I3) -> 88 | BA3: =IF(AO3="","",P3) -> 0 | BB3: =IF(AO3="","",Q3) -> 0 | BC3: =IF(AO3="","",K3) -> 91.94 | BF3: =IF(AO3=0,"",200) -> 200 | BH3: =IF(AO3="","",V3) -> 64000
B4: MTU-07 | C4: ERZK-163 | D4: UBAH | E4: ESP | F4: OPEN | G4: 170 | H4: 149 | I4: 156 | J4: 1039 | K4: 92.25 | L4: =IF(WELLNAME="","",(FLUIDTOTAL*(1-(WC/100)))) -> 80.5225 | N4: =IF(ISNUMBER(M4),(M4*10^6)/L4,"") | O4: 5.5 | R4: 779 | S4: 55 | T4: 0 | U4: OP/F | V4: 70000 | W4: W.C F/ (MTU 92.25 %, LAB 88.65 %, WHS 89.2 %). AMP= 23.3-23.4, HZ= 55, H2S= 4 PPM, CO2= 1 %, API= 30.7, CL= 70 KPPM, MF= 0.95, PIP= 779 PSI. | AO4: =IF(C3="",0,"KHALDA_WELLTEST1") -> KHALDA_WELLTEST1 | AP4: =IF(AO4="","",REPORTDATE-1) -> 46284 | AQ4: =UPPER(IF(AO4="","",$AN$3&C4)) -> 9ERZK-163 | AR4: =UPPER(IF(AO4="","",$AN$3&C4)) -> 9ERZK-163 | AS4: =IF(AO4="","",O4) -> 5.5 | AT4: =IF(AO4=0,"",X4) -> 0 | AU4: =IF(AO4="","",J4) -> 1039 | AV4: =IF(AO4="","",M4*1000) -> 0 | AW4: =IF(AO4="","",F4) -> OPEN | AX4: =IF(AO4="","",G4) -> 170 | AY4: =IF(AO4="","",H4) -> 149 | AZ4: =IF(AO4="","",I4) -> 156 | BA4: =IF(AO4="","",P4) -> 0 | BB4: =IF(AO4="","",Q4) -> 0 | BC4: =IF(AO4="","",K4) -> 92.25 | BF4: =IF(AO4=0,"",200) -> 200 | BH4: =IF(AO4="","",V4) -> 70000
L5: =IF(WELLNAME="","",(FLUIDTOTAL*(1-(WC/100)))) | N5: =IF(ISNUMBER(M5),(M5*10^6)/L5,"") | AO5: =IF(C4="",0,"KHALDA_WELLTEST1") -> KHALDA_WELLTEST1 | AP5: =IF(AO5="","",REPORTDATE-1) -> 46284 | AQ5: =UPPER(IF(AO5="","",$AN$3&C5)) -> 9 | AR5: =UPPER(IF(AO5="","",$AN$3&C5)) -> 9 | AS5: =IF(AO5="","",O5) -> 0 | AT5: =IF(AO5=0,"",X5) -> 0 | AU5: =IF(AO5="","",J5) -> 0 | AV5: =IF(AO5="","",M5*1000) -> 0 | AW5: =IF(AO5="","",F5) -> 0 | AX5: =IF(AO5="","",G5) -> 0 | AY5: =IF(AO5="","",H5) -> 0 | AZ5: =IF(AO5="","",I5) -> 0 | BA5: =IF(AO5="","",P5) -> 0 | BB5: =IF(AO5="","",Q5) -> 0 | BC5: =IF(AO5="","",K5) -> 0 | BF5: =IF(AO5=0,"",200) -> 200 | BH5: =IF(AO5="","",V5) -> 0
L6: =IF(WELLNAME="","",(FLUIDTOTAL*(1-(WC/100)))) | N6: =IF(ISNUMBER(M6),(M6*10^6)/L6,"") | AO6: =IF(C5="",0,"KHALDA_WELLTEST1") -> 0 | AP6: =IF(AO6="","",REPORTDATE-1) -> 46284 | AQ6: =UPPER(IF(AO6="","",$AN$3&C6)) -> 9 | AR6: =UPPER(IF(AO6="","",$AN$3&C6)) -> 9 | AS6: =IF(AO6="","",O6) -> 0 | AT6: =IF(AO6=0,"",X6) | AU6: =IF(AO6="","",J6) -> 0 | AV6: =IF(AO6="","",M6*1000) -> 0 | AW6: =IF(AO6="","",F6) -> 0 | AX6: =IF(AO6="","",G6) -> 0 | AY6: =IF(AO6="","",H6) -> 0 | AZ6: =IF(AO6="","",I6) -> 0 | BA6: =IF(AO6="","",P6) -> 0 | BB6: =IF(AO6="","",Q6) -> 0 | BC6: =IF(AO6="","",K6) -> 0 | BF6: =IF(AO6=0,"",200) | BH6: =IF(AO6="","",V6) -> 0
L7: =IF(WELLNAME="","",(FLUIDTOTAL*(1-(WC/100)))) | N7: =IF(ISNUMBER(M7),(M7*10^6)/L7,"") | AO7: =IF(C6="",0,"KHALDA_WELLTEST1") -> 0 | AP7: =IF(AO7="","",REPORTDATE-1) -> 46284 | AQ7: =UPPER(IF(AO7="","",$AN$3&C7)) -> 9 | AR7: =UPPER(IF(AO7="","",$AN$3&C7)) -> 9 | AS7: =IF(AO7="","",O7) -> 0 | AT7: =IF(AO7=0,"",X7) | AU7: =IF(AO7="","",J7) -> 0 | AV7: =IF(AO7="","",M7*1000) -> 0 | AW7: =IF(AO7="","",F7) -> 0 | AX7: =IF(AO7="","",G7) -> 0 | AY7: =IF(AO7="","",H7) -> 0 | AZ7: =IF(AO7="","",I7) -> 0 | BA7: =IF(AO7="","",P7) -> 0 | BB7: =IF(AO7="","",Q7) -> 0 | BC7: =IF(AO7="","",K7) -> 0 | BF7: =IF(AO7=0,"",200) | BH7: =IF(AO7="","",V7) -> 0
L8: =IF(WELLNAME="","",(FLUIDTOTAL*(1-(WC/100)))) | N8: =IF(ISNUMBER(M8),(M8*10^6)/L8,"") | AO8: =IF(C7="",0,"KHALDA_WELLTEST1") -> 0 | AP8: =IF(AO8="","",REPORTDATE-1) -> 46284 | AQ8: =UPPER(IF(AO8="","",$AN$3&C8)) -> 9 | AR8: =UPPER(IF(AO8="","",$AN$3&C8)) -> 9 | AS8: =IF(AO8="","",O8) -> 0 | AT8: =IF(AO8=0,"",X8) | AU8: =IF(AO8="","",J8) -> 0 | AV8: =IF(AO8="","",M8*1000) -> 0 | AW8: =IF(AO8="","",F8) -> 0 | AX8: =IF(AO8="","",G8) -> 0 | AY8: =IF(AO8="","",H8) -> 0 | AZ8: =IF(AO8="","",I8) -> 0 | BA8: =IF(AO8="","",P8) -> 0 | BB8: =IF(AO8="","",Q8) -> 0 | BC8: =IF(AO8="","",K8) -> 0 | BF8: =IF(AO8=0,"",200) | BH8: =IF(AO8="","",V8) -> 0
L9: =IF(WELLNAME="","",(FLUIDTOTAL*(1-(WC/100)))) | N9: =IF(ISNUMBER(M9),(M9*10^6)/L9,"") | AO9: =IF(C8="",0,"KHALDA_WELLTEST1") -> 0 | AP9: =IF(AO9="","",REPORTDATE-1) -> 46284 | AQ9: =UPPER(IF(AO9="","",$AN$3&C9)) -> 9 | AR9: =UPPER(IF(AO9="","",$AN$3&C9)) -> 9 | AS9: =IF(AO9="","",O9) -> 0 | AT9: =IF(AO9=0,"",X9) | AU9: =IF(AO9="","",J9) -> 0 | AV9: =IF(AO9="","",M9*1000) -> 0 | AW9: =IF(AO9="","",F9) -> 0 | AX9: =IF(AO9="","",G9) -> 0 | AY9: =IF(AO9="","",H9) -> 0 | AZ9: =IF(AO9="","",I9) -> 0 | BA9: =IF(AO9="","",P9) -> 0 | BB9: =IF(AO9="","",Q9) -> 0 | BC9: =IF(AO9="","",K9) -> 0 | BF9: =IF(AO9=0,"",200) | BH9: =IF(AO9="","",V9) -> 0
L10: =IF(WELLNAME="","",(FLUIDTOTAL*(1-(WC/100)))) | N10: =IF(ISNUMBER(M10),(M10*10^6)/L10,"") | AO10: =IF(C9="",0,"KHALDA_WELLTEST1") -> 0 | AP10: =IF(AO10="","",REPORTDATE-1) -> 46284 | AQ10: =UPPER(IF(AO10="","",$AN$3&C10)) -> 9 | AR10: =UPPER(IF(AO10="","",$AN$3&C10)) -> 9 | AS10: =IF(AO10="","",O10) -> 0 | AT10: =IF(AO10=0,"",X10) | AU10: =IF(AO10="","",J10) -> 0 | AV10: =IF(AO10="","",M10*1000) -> 0 | AW10: =IF(AO10="","",F10) -> 0 | AX10: =IF(AO10="","",G10) -> 0 | AY10: =IF(AO10="","",H10) -> 0 | AZ10: =IF(AO10="","",I10) -> 0 | BA10: =IF(AO10="","",P10) -> 0 | BB10: =IF(AO10="","",Q10) -> 0 | BC10: =IF(AO10="","",K10) -> 0 | BF10: =IF(AO10=0,"",200) | BH10: =IF(AO10="","",V10) -> 0
L11: =IF(WELLNAME="","",(FLUIDTOTAL*(1-(WC/100)))) | N11: =IF(ISNUMBER(M11),(M11*10^6)/L11,"") | AO11: =IF(C10="",0,"KHALDA_WELLTEST1") -> 0 | AP11: =IF(AO11="","",REPORTDATE-1) -> 46284 | AQ11: =UPPER(IF(AO11="","",$AN$3&C11)) -> 9 | AR11: =UPPER(IF(AO11="","",$AN$3&C11)) -> 9 | AS11: =IF(AO11="","",O11) -> 0 | AT11: =IF(AO11=0,"",X11) | AU11: =IF(AO11="","",J11) -> 0 | AV11: =IF(AO11="","",M11*1000) -> 0 | AW11: =IF(AO11="","",F11) -> 0 | AX11: =IF(AO11="","",G11) -> 0 | AY11: =IF(AO11="","",H11) -> 0 | AZ11: =IF(AO11="","",I11) -> 0 | BA11: =IF(AO11="","",P11) -> 0 | BB11: =IF(AO11="","",Q11) -> 0 | BC11: =IF(AO11="","",K11) -> 0 | BF11: =IF(AO11=0,"",200) | BH11: =IF(AO11="","",V11) -> 0
L12: =IF(WELLNAME="","",(FLUIDTOTAL*(1-(WC/100)))) | N12: =IF(ISNUMBER(M12),(M12*10^6)/L12,"") | AO12: =IF(C11="",0,"KHALDA_WELLTEST1") -> 0 | AP12: =IF(AO12="","",REPORTDATE-1) -> 46284 | AQ12: =UPPER(IF(AO12="","",$AN$3&C12)) -> 9 | AR12: =UPPER(IF(AO12="","",$AN$3&C12)) -> 9 | AS12: =IF(AO12="","",O12) -> 0 | AT12: =IF(AO12=0,"",X12) | AU12: =IF(AO12="","",J12) -> 0 | AV12: =IF(AO12="","",M12*1000) -> 0 | AW12: =IF(AO12="","",F12) -> 0 | AX12: =IF(AO12="","",G12) -> 0 | AY12: =IF(AO12="","",H12) -> 0 | AZ12: =IF(AO12="","",I12) -> 0 | BA12: =IF(AO12="","",P12) -> 0 | BB12: =IF(AO12="","",Q12) -> 0 | BC12: =IF(AO12="","",K12) -> 0 | BF12: =IF(AO12=0,"",200) | BH12: =IF(AO12="","",V12) -> 0
L13: =IF(WELLNAME="","",(FLUIDTOTAL*(1-(WC/100)))) | N13: =IF(ISNUMBER(M13),(M13*10^6)/L13,"") | AO13: =IF(C12="",0,"KHALDA_WELLTEST1") -> 0 | AP13: =IF(AO13="","",REPORTDATE-1) -> 46284 | AQ13: =UPPER(IF(AO13="","",$AN$3&C13)) -> 9 | AR13: =UPPER(IF(AO13="","",$AN$3&C13)) -> 9 | AS13: =IF(AO13="","",O13) -> 0 | AT13: =IF(AO13=0,"",X13) | AU13: =IF(AO13="","",J13) -> 0 | AV13: =IF(AO13="","",M13*1000) -> 0 | AW13: =IF(AO13="","",F13) -> 0 | AX13: =IF(AO13="","",G13) -> 0 | AY13: =IF(AO13="","",H13) -> 0 | AZ13: =IF(AO13="","",I13) -> 0 | BA13: =IF(AO13="","",P13) -> 0 | BB13: =IF(AO13="","",Q13) -> 0 | BC13: =IF(AO13="","",K13) -> 0 | BF13: =IF(AO13=0,"",200) | BH13: =IF(AO13="","",V13) -> 0
B14: PREVIOUS WELL TEST | AT14: =IF(AO14=0,"",X14) | AY14: =IF(AO14="","",H14) | BH14: =IF(AO14="","",V14)
B15: TEST FACILITY | C15: WELL NAME | D15: ZONE | E15: STATUS | F15: CHOKE 64" | G15: WHP PSI | H15: WHT °F | I15: SEP PSI | J15: BFPD STB | K15: BS&W % | L15: BOPD STB | M15: GAS MMSCF | N15: GOR scf/bbl | O15: HRS ON TEST | P15: DFL | Q15: NLAP | T15: CSG PSI | U15: CSG STATUS | V15: TEST DATE | W15: COMMENTS | AT15: =IF(AO15=0,"",X15) | AY15: =IF(AO15="","",H15) | BH15: =IF(AO15="","",V15)
B16: MTU-07 | C16: MRZK-76 | D16: BAH | E16: ESP | F16: SPOOL | G16: 110 | H16: 149 | I16: 91 | J16: 1146 | K16: 92 | L16: =J16*(1-K16/100) -> 91.68 | O16: 7 | R16: 888 | S16: 59 | T16: N/A | U16: OP/P | V16: 46269 | W16: W.C F/ (MTU 92 %, LAB 91.7 %, WHS 90.5 %). AMP= 26.6-26.7, HZ= 59, H2S= 0 PPM, CO2= 1 %, API= 29.1, CL= 64 KPPM, MF= 0.94, PIP= 888 PSI. | AO16: =IF(C16="",0,"KHALDA_WELLTEST1") -> KHALDA_WELLTEST1 | AP16: =IF(AO16="","",REPORTDATE-1) -> 46284 | AQ16: =UPPER(IF(AO16="","",$AN$3&C16)) -> 9MRZK-76 | AR16: =UPPER(IF(AO16="","",$AN$3&C16)) -> 9MRZK-76 | AS16: =IF(AO16="","",#REF!) -> #REF! | AT16: =IF(AO16=0,"",X16) -> 0 | AU16: =IF(AO16="","",J16) -> 1146 | AV16: =IF(AO16="","",N16*1000) -> #VALUE! | AW16: =IF(AO16="","",E16) -> ESP | AX16: =IF(AO16="","",G16) -> 110 | AY16: =IF(AO16="","",H16) -> 149 | AZ16: =IF(AO16="","",I16) -> 91 | BA16: =IF(AO16="","",P16) -> 0 | BB16: =IF(AO16="","",Q16) -> 0 | BC16: =IF(AO16="","",K16) -> 92 | BF16: =IF(AO16=0,"",200) -> 200 | BH16: =IF(AO16="","",V16) -> 46269
B17: MTU-07 | C17: ERZK-163 | D17: UBAH | E17: ESP | F17: OPEN | G17: 170 | H17: 145 | I17: 155 | J17: 1032 | K17: 91.6 | L17: =J17*(1-K17/100) -> 86.688 | O17: 7 | R17: 790 | S17: 55 | T17: 0 | U17: CL | V17: 46226 | W17: W.C F/ (MTU 91.6 %, LAB 90.2 %, WHS 90 %). AMP= 22.3, HZ= 55, H2S= 3 PPM, CO2= 1 %, API= 30.7, CL= 70 KPPM, MF= 0.95, PIP= 790 PSI. | AT17: =IF(AO17=0,"",X17) | AY17: =IF(AO17="","",H17) | BH17: =IF(AO17="","",V17)
L18: =J18*(1-K18/100) -> 0 | AO18: =IF(C18="",0,"KHALDA_WELLTEST1") -> 0 | AP18: =IF(AO18="","",REPORTDATE-1) -> 46284 | AQ18: =UPPER(IF(AO18="","",$AN$3&C18)) -> 9 | AR18: =UPPER(IF(AO18="","",$AN$3&C18)) -> 9 | AS18: =IF(AO18="","",O18) -> 0 | AT18: =IF(AO18=0,"",X18) | AU18: =IF(AO18="","",J18) -> 0 | AV18: =IF(AO18="","",M18*1000) -> 0 | AW18: =IF(AO18="","",E18) -> 0 | AX18: =IF(AO18="","",G18) -> 0 | AY18: =IF(AO18="","",H18) -> 0 | AZ18: =IF(AO18="","",I18) -> 0 | BA18: =IF(AO18="","",P18) -> 0 | BB18: =IF(AO18="","",Q18) -> 0 | BC18: =IF(AO18="","",K18) -> 0 | BF18: =IF(AO18=0,"",200) | BH18: =IF(AO18="","",V18) -> 0
L19: =J19*(1-K19/100) -> 0 | N19: =IF(ISNUMBER(M19),(M19*10^6)/L19,"") | AO19: =IF(C19="",0,"KHALDA_WELLTEST1") -> 0 | AP19: =IF(AO19="","",REPORTDATE-1) -> 46284 | AQ19: =UPPER(IF(AO19="","",$AN$3&C19)) -> 9 | AR19: =UPPER(IF(AO19="","",$AN$3&C19)) -> 9 | AS19: =IF(AO19="","",O19) -> 0 | AT19: =IF(AO19=0,"",X19) | AU19: =IF(AO19="","",J19) -> 0 | AV19: =IF(AO19="","",M19*1000) -> 0 | AW19: =IF(AO19="","",E19) -> 0 | AX19: =IF(AO19="","",G19) -> 0 | AY19: =IF(AO19="","",H19) -> 0 | AZ19: =IF(AO19="","",I19) -> 0 | BA19: =IF(AO19="","",P19) -> 0 | BB19: =IF(AO19="","",Q19) -> 0 | BC19: =IF(AO19="","",K19) -> 0 | BF19: =IF(AO19=0,"",200) | BH19: =IF(AO19="","",V19) -> 0
L20: =J20*(1-K20/100) -> 0 | N20: =IF(ISNUMBER(M20),(M20*10^6)/L20,"") | AO20: =IF(C20="",0,"KHALDA_WELLTEST1") -> 0 | AP20: =IF(AO20="","",REPORTDATE-1) -> 46284 | AQ20: =UPPER(IF(AO20="","",$AN$3&C20)) -> 9 | AR20: =UPPER(IF(AO20="","",$AN$3&C20)) -> 9 | AS20: =IF(AO20="","",O20) -> 0 | AT20: =IF(AO20=0,"",X20) | AU20: =IF(AO20="","",J20) -> 0 | AV20: =IF(AO20="","",M20*1000) -> 0 | AW20: =IF(AO20="","",E20) -> 0 | AX20: =IF(AO20="","",G20) -> 0 | AY20: =IF(AO20="","",H20) -> 0 | AZ20: =IF(AO20="","",I20) -> 0 | BA20: =IF(AO20="","",P20) -> 0 | BB20: =IF(AO20="","",Q20) -> 0 | BC20: =IF(AO20="","",K20) -> 0 | BF20: =IF(AO20=0,"",200) | BH20: =IF(AO20="","",V20) -> 0
L21: =J21*(1-K21/100) -> 0 | N21: =IF(ISNUMBER(M21),(M21*10^6)/L21,"") | AO21: =IF(C21="",0,"KHALDA_WELLTEST1") -> 0 | AP21: =IF(AO21="","",REPORTDATE-1) -> 46284 | AQ21: =UPPER(IF(AO21="","",$AN$3&C21)) -> 9 | AR21: =UPPER(IF(AO21="","",$AN$3&C21)) -> 9 | AS21: =IF(AO21="","",O21) -> 0 | AT21: =IF(AO21=0,"",X21) | AU21: =IF(AO21="","",J21) -> 0 | AV21: =IF(AO21="","",M21*1000) -> 0 | AW21: =IF(AO21="","",F21) -> 0 | AX21: =IF(AO21="","",G21) -> 0 | AY21: =IF(AO21="","",H21) -> 0 | AZ21: =IF(AO21="","",I21) -> 0 | BA21: =IF(AO21="","",P21) -> 0 | BB21: =IF(AO21="","",Q21) -> 0 | BC21: =IF(AO21="","",K21) -> 0 | BF21: =IF(AO21=0,"",200) | BH21: =IF(AO21="","",V21) -> 0
L22: =J22*(1-K22/100) -> 0 | N22: =IF(ISNUMBER(M22),(M22*10^6)/L22,"") | AO22: =IF(C22="",0,"KHALDA_WELLTEST1") -> 0 | AP22: =IF(AO22="","",REPORTDATE-1) -> 46284 | AQ22: =UPPER(IF(AO22="","",$AN$3&C22)) -> 9 | AR22: =UPPER(IF(AO22="","",$AN$3&C22)) -> 9 | AS22: =IF(AO22="","",O22) -> 0 | AT22: =IF(AO22=0,"",X22) | AU22: =IF(AO22="","",J22) -> 0 | AV22: =IF(AO22="","",M22*1000) -> 0 | AW22: =IF(AO22="","",F22) -> 0 | AX22: =IF(AO22="","",G22) -> 0 | AY22: =IF(AO22="","",H22) -> 0 | AZ22: =IF(AO22="","",I22) -> 0 | BA22: =IF(AO22="","",P22) -> 0 | BB22: =IF(AO22="","",Q22) -> 0 | BC22: =IF(AO22="","",K22) -> 0 | BF22: =IF(AO22=0,"",200) | BH22: =IF(AO22="","",V22) -> 0
L23: =J23*(1-K23/100) -> 0 | N23: =IF(ISNUMBER(M23),(M23*10^6)/L23,"") | AO23: =IF(C23="",0,"KHALDA_WELLTEST1") -> 0 | AP23: =IF(AO23="","",REPORTDATE-1) -> 46284 | AQ23: =UPPER(IF(AO23="","",$AN$3&C23)) -> 9 | AR23: =UPPER(IF(AO23="","",$AN$3&C23)) -> 9 | AS23: =IF(AO23="","",O23) -> 0 | AT23: =IF(AO23=0,"",X23) | AU23: =IF(AO23="","",J23) -> 0 | AV23: =IF(AO23="","",M23*1000) -> 0 | AW23: =IF(AO23="","",F23) -> 0 | AX23: =IF(AO23="","",G23) -> 0 | AY23: =IF(AO23="","",H23) -> 0 | AZ23: =IF(AO23="","",I23) -> 0 | BA23: =IF(AO23="","",P23) -> 0 | BB23: =IF(AO23="","",Q23) -> 0 | BC23: =IF(AO23="","",K23) -> 0 | BF23: =IF(AO23=0,"",200) | BH23: =IF(AO23="","",V23) -> 0
L24: =J24*(1-K24/100) -> 0 | N24: =IF(ISNUMBER(M24),(M24*10^6)/L24,"") | AO24: =IF(C24="",0,"KHALDA_WELLTEST1") -> 0 | AP24: =IF(AO24="","",REPORTDATE-1) -> 46284 | AQ24: =UPPER(IF(AO24="","",$AN$3&C24)) -> 9 | AR24: =UPPER(IF(AO24="","",$AN$3&C24)) -> 9 | AS24: =IF(AO24="","",O24) -> 0 | AT24: =IF(AO24=0,"",X24) | AU24: =IF(AO24="","",J24) -> 0 | AV24: =IF(AO24="","",M24*1000) -> 0 | AW24: =IF(AO24="","",F24) -> 0 | AX24: =IF(AO24="","",G24) -> 0 | AY24: =IF(AO24="","",H24) -> 0 | AZ24: =IF(AO24="","",I24) -> 0 | BA24: =IF(AO24="","",P24) -> 0 | BB24: =IF(AO24="","",Q24) -> 0 | BC24: =IF(AO24="","",K24) -> 0 | BF24: =IF(AO24=0,"",200) | BH24: =IF(AO24="","",V24) -> 0
L25: =J25*(1-K25/100) -> 0 | N25: =IF(ISNUMBER(M25),(M25*10^6)/L25,"") | V25: ` | AO25: =IF(C25="",0,"KHALDA_WELLTEST1") -> 0 | AP25: =IF(AO25="","",REPORTDATE-1) -> 46284 | AQ25: =UPPER(IF(AO25="","",$AN$3&C25)) -> 9 | AR25: =UPPER(IF(AO25="","",$AN$3&C25)) -> 9 | AS25: =IF(AO25="","",O25) -> 0 | AT25: =IF(AO25=0,"",X25) | AU25: =IF(AO25="","",J25) -> 0 | AV25: =IF(AO25="","",M25*1000) -> 0 | AW25: =IF(AO25="","",F25) -> 0 | AX25: =IF(AO25="","",G25) -> 0 | AY25: =IF(AO25="","",H25) -> 0 | AZ25: =IF(AO25="","",I25) -> 0 | BA25: =IF(AO25="","",P25) -> 0 | BB25: =IF(AO25="","",Q25) -> 0 | BC25: =IF(AO25="","",K25) -> 0 | BF25: =IF(AO25=0,"",200) | BH25: =IF(AO25="","",V25) -> `
AO26: =IF(C26="",0,"KHALDA_WELLTEST1") -> 0 | AP26: =IF(AO26="","",REPORTDATE-1) -> 46284 | AQ26: =UPPER(IF(AO26="","",$AN$3&C26)) -> 9 | AR26: =UPPER(IF(AO26="","",$AN$3&C26)) -> 9 | AS26: =IF(AO26="","",O26) -> 0 | AT26: =IF(AO26=0,"",X26) | AU26: =IF(AO26="","",J26) -> 0 | AV26: =IF(AO26="","",M26*1000) -> 0 | AW26: =IF(AO26="","",F26) -> 0 | AX26: =IF(AO26="","",G26) -> 0 | AY26: =IF(AO26="","",H26) -> 0 | AZ26: =IF(AO26="","",I26) -> 0 | BA26: =IF(AO26="","",P26) -> 0 | BB26: =IF(AO26="","",Q26) -> 0 | BC26: =IF(AO26="","",K26) -> 0 | BF26: =IF(AO26=0,"",200) | BH26: =IF(AO26="","",V26) -> 0
AO27: =IF(C27="",0,"KHALDA_WELLTEST1") -> 0 | AP27: =IF(AO27="","",REPORTDATE-1) -> 46284 | AQ27: =UPPER(IF(AO27="","",$AN$3&C27)) -> 9 | AR27: =UPPER(IF(AO27="","",$AN$3&C27)) -> 9 | AS27: =IF(AO27="","",O27) -> 0 | AT27: =IF(AO27=0,"",X27) | AU27: =IF(AO27="","",J27) -> 0 | AV27: =IF(AO27="","",M27*1000) -> 0 | AW27: =IF(AO27="","",F27) -> 0 | AX27: =IF(AO27="","",G27) -> 0 | AY27: =IF(AO27="","",H27) -> 0 | AZ27: =IF(AO27="","",I27) -> 0 | BA27: =IF(AO27="","",P27) -> 0 | BB27: =IF(AO27="","",Q27) -> 0 | BC27: =IF(AO27="","",K27) -> 0 | BF27: =IF(AO27=0,"",200) | BH27: =IF(AO27="","",V27) -> 0

Sheet WELL DATA
B1: WELL DATA - OIL WELLS | F1: =SUMIF(WSTATUS,"=SI",HOURS) -> 0 | J1: TEMPLATE MOD NEEDED | Q1: =REPORT!#REF! -> #REF! | AC1: NRQ PROFAC | AD1: =REPORT!M8/(SUMIF(FIELD,"NRQ",EST_PROD)) -> 0.77925307 | AI1: =REPORT!M7/((SUMIF(FIELD,"MAIN",EST_PROD))+(SUMIF(FIELD,"EAST",EST_PROD))+(SUMIF(FIELD,"NORTH",EST_PROD))+(SUMIF(FIELD,"WEST",EST_PROD))) -> 1.0944361 | AK1: Test is > 30 days old
B2: WELL NAME | C2: ZONE | D2: WELL TYPE | E2: STATUS | F2: =IF(F1>0,"CHECK HRS","HRS ONLINE") -> HRS ONLINE | G2: DEFER'd PROD STB | H2: DOWNTIME CAUSE Input will be blue if cause required | I2: H2S READING | J2: CHOKE 64" | K2: WHFP PSI | L2: F/LINE PSI | M2: CASING PSI | N2: CASING STATUS | O2: FTHT °F | P2: FLUID LEVELS | U2: PUMP DEPTH | V2: PUMP SIZE " | W2: DAILY SAM DATA | AA2: SUCKER ROD PUMP DATA | AE2: AMPS | AF2: Hz | AG2: Motor Rating AMP | AH2: Motor Loading Percentage | AI2: EST PRODN | AJ2: LAST WELL TEST | AP2: COMMENTS | CV2: =CY153/CY158 -> 1.0786916 | CW2: FV TAG | CX2: DATE | CY2: WELL NAME | CZ2: CHOKE 64" | DA2: WHFP PSI | DB2: HRS ONLINE | DC2: STATUS | DD2: WHSIP | DE2: LIFT GAS | DF2: FTHT | DG2: DHP | DH2: SPM | DI2: SL | DJ2: RPM | DK2: AMP 1 | DL2: AMP 2 | DM2: AMP 3 | DN2: HZ | DO2: DAILY BS&W | DP2: DOWNTIME CAUSE | DQ2: EST PROD | DR2: LIFT GAS MMSCF/D | DS2: FIELD | DY2: FV TAG | DZ2: DATE | EA2: WELL NAME | EB2: CHOKE 64" | EC2: WHFP PSI | ED2: HRS ONLINE | EE2: STATUS | EF2: CSG PSI | EG2: CSG STAT | EH2: DOWNTIME CAUSE | EI2: DAILY BS&W | EJ2: PUMP SIZE | EK2: DEFER PROD | EL2: FLINE PSI | EM2: PUMP UNIT SIZE | EN2: SPM"Strock Per Minute" | EO2: DATE OF DOWNLOAD | EP2: SL"Strock Length" | EQ2: AMP1 | ER2: AMP2 | ES2: AMP3 | ET2: RPM | EU2: HZ | EV2: PUMP TYPE | EW2: RUNTIME % | EX2: INF PROD | EY2: PUMP FILLAGE% | EZ2: PUMP FILL SET PT% | FA2: COMMENTS | FB2: FIELD
P3: LAST DATE | Q3: DFL | R3: L% | S3: NLAP | T3: SFL | W3: RUNTIME % | X3: INF PROD | Y3: PUMP FILLAGE% | Z3: PUMP FILL SET PT% | AA3: SRU | AB3: SPM | AC3: SL | AD3: RPM | AJ3: DATE | AK3: BFPD | AL3: GAS (mmscf) | AM3: BS&W % | AN3: BOPD | AO3: CL, PPM | CV3: 9
C4: WRZK-60 | D4: ARG | F4: Spool | G4: =IF(OR(WSTATUS="T&A",DTCAUSE="PUMP OFF MODE",DTCAUSE="UNDER LOAD"),0,BOPD/24*(24-HOURS)) -> #VALUE! | T4: W.C F/ (MTU **** %, Lab *** %, WHS *** %), H2S= *** PPM, CO2= *** %, SAM Reading= *** @ *** % R.T, P.F=**** %, CL=*** Kppm, MF=*** | AI4: =AN4/24*F4 -> #VALUE! | AL4: mmscf | AN4: =IF(BFPD=0,0,BFPD*(1-BSW/100)) -> 0 | CW4: KHALDA_WELL | CX4: =REPORTDATE-1 -> 46284 | CY4: =$CV$3&B4 -> 9 | CZ4: =J4 -> 0 | DA4: =K4 -> 0 | DB4: =F4 -> Spool | DC4: =IF(DB4=0,"SI",E4) -> 0 | DF4: =O4 -> 0 | DG4: =AA4 -> 0 | DH4: =AB4 -> 0 | DI4: =AC4 -> 0 | DJ4: =AD4 -> 0 | DK4: =AE4 -> 0 | DN4: =AF4 -> 0 | DO4: =AI4 -> #VALUE! | DP4: =IF(H4="","",H4) | DQ4: =AN4/24*HOURS -> #VALUE! | DR4: =I4 -> 0 | DS4: =IF(OR(E4="SI",B4="",E4="T&A"),"",VLOOKUP(B4,WELL_FIELD,2))
B5: ERZK-17 | C5: APOLLONIA | E5: SI | F5: 0 | G5: =IF(OR(WSTATUS="T&A",DTCAUSE="PUMP OFF MODE",DTCAUSE="UNDER LOAD"),0,BOPD/24*(24-HOURS)) -> 0 | I5: 24000 | K5: 0 | S5: PKR | U5: 3479 | V5: 1.75 | AA5: C-456 | AH5: =IF(AG5="","",AE5/AG5*100) | AI5: =AN5/24*F5 -> 0 | AN5: =IF(BFPD=0,0,BFPD*(1-BSW/100)) -> 0 | AO5: 0 | AP5: DH Problem 31-10-22 Last W/O 08/2021 (R/C - Acidize Apollonia Reservoir Interval), started up 03/09/2021. | BJ5: =+IF(E5="SI",0,AK5*AM5/100) -> 0 | CW5: KHALDA_WELL | CX5: =REPORTDATE-1 -> 46284 | CY5: =$CV$3&B5 -> 9ERZK-17 | CZ5: =J5 -> 0 | DA5: =K5 -> 0 | DB5: =F5 -> 0 | DC5: =IF(DB5=0,"SI",E5) -> SI | DF5: =O5 -> 0 | DG5: =AA5 -> C-456 | DH5: =AB5 -> 0 | DI5: =AC5 -> 0 | DJ5: =AD5 -> 0 | DK5: =AE5 -> 0 | DN5: =AF5 -> 0 | DO5: =AI5 -> 0 | DP5: =IF(H5="","",H5) | DQ5: =AN5/24*HOURS -> 0 | DR5: =I5 -> 24000 | DS5: =IF(OR(E5="SI",B5="",E5="T&A"),"",VLOOKUP(B5,WELL_FIELD,2)) | DY5: =IF(B5="","","KHALDA_WELL") -> KHALDA_WELL | DZ5: =REPORTDATE-1 -> 46284 | EA5: =B5 -> ERZK-17 | EB5: =J5 -> 0 | EC5: =K5 -> 0 | ED5: =F5 -> 0 | EE5: =IF(DB5=0,"SI",E5) -> SI | EH5: =IF(H5="","",H5) | EI5: =AI5 -> 0 | EJ5: =V5 -> 1.75 | EK5: =G5 -> 0 | EN5: =AB5 -> 0 | EP5: =AC5 -> 0 | EQ5: =AE5 -> 0 | ET5: =AD5 -> 0 | EU5: =AF5 -> 0 | EW5: =W5 -> 0 | EX5: =X5 -> 0 | EY5: =Y5 -> 0 | EZ5: =Z5 -> 0 | FA5: =AP5 -> DH Problem 31-10-22 Last W/O 08/2021 (R/C - Acidize Apollonia Reservoir Interval), started up 03/09/2021. | FB5: =IF(OR(E5="SI",B5="",E5="T&A"),"",VLOOKUP(B5,WELL_FIELD,2))
B6: ERZK-18 | C6: BAH | D6: SRP | E6: SI | F6: 0 | G6: =IF(OR(WSTATUS="T&A",DTCAUSE="PUMP OFF MODE",DTCAUSE="UNDER LOAD"),0,BOPD/24*(24-HOURS)) -> 0 | K6: 0 | S6: PKR | U6: 5511 | V6: GN2100 | AI6: =AN6/24*F6 -> 0 | AN6: =IF(BFPD=0,0,BFPD*(1-BSW/100)) -> 0 | AP6: S/D on 17-02-2023 due to DH Problem Last W/O 02/2021 (R/C), started up 07/02/2021. | BJ6: =+IF(E6="SI",0,AK6*AM6/100) -> 0 | CW6: KHALDA_WELL | CX6: =REPORTDATE-1 -> 46284 | CY6: =$CV$3&B6 -> 9ERZK-18 | CZ6: =J6 -> 0 | DA6: =K6 -> 0 | DB6: =F6 -> 0 | DC6: =IF(DB6=0,"SI",E6) -> SI | DF6: =O6 -> 0 | DG6: =AA6 -> 0 | DH6: =AB6 -> 0 | DI6: =AC6 -> 0 | DJ6: =AD6 -> 0 | DK6: =AE6 -> 0 | DN6: =AF6 -> 0 | DO6: =AI6 -> 0 | DP6: =IF(H6="","",H6) | DQ6: =AN6/24*HOURS -> 0 | DR6: =I6 -> 0 | DS6: =IF(OR(E6="SI",B6="",E6="T&A"),"",VLOOKUP(B6,WELL_FIELD,2)) | DY6: =IF(B6="","","KHALDA_WELL") -> KHALDA_WELL | DZ6: =REPORTDATE-1 -> 46284 | EA6: =B6 -> ERZK-18 | EB6: =J6 -> 0 | EC6: =K6 -> 0 | ED6: =F6 -> 0 | EE6: =IF(DB6=0,"SI",E6) -> SI | EH6: =IF(H6="","",H6) | EI6: =AI6 -> 0 | EJ6: =V6 -> GN2100 | EK6: =G6 -> 0 | EN6: =AB6 -> 0 | EP6: =AC6 -> 0 | EQ6: =AE6 -> 0 | ET6: =AD6 -> 0 | EU6: =AF6 -> 0 | EW6: =W6 -> 0 | EX6: =X6 -> 0 | EY6: =Y6 -> 0 | EZ6: =Z6 -> 0 | FA6: =AP6 -> S/D on 17-02-2023 due to DH Problem Last W/O 02/2021 (R/C), started up 07/02/2021. | FB6: =IF(OR(E6="SI",B6="",E6="T&A"),"",VLOOKUP(B6,WELL_FIELD,2))
B7: ERZK-21 | C7: BAH/ARG | D7: SRP | E7: ESP | F7: 24 | G7: =IF(OR(WSTATUS="T&A",DTCAUSE="PUMP OFF MODE",DTCAUSE="UNDER LOAD"),0,BOPD/24*(24-HOURS)) -> 0 | I7: 6 | J7: 128 | K7: 170 | L7: 160 | M7: 0 | N7: CL | O7: 156 | P7: 46113 | Q7: 3695.66 | R7: 100 | S7: 1725 | U7: 5421 | V7: SN3600 | AE7: 50 | AF7: 50 | AG7: 61.7 | AH7: =IF(AG7="","",AE7/AG7*100) -> 81.037277 | AI7: =AN7/24*F7 -> 76.76 | AJ7: 46277 | AK7: 1919 | AM7: 96 | AN7: =IF(BFPD=0,0,BFPD*(1-BSW/100)) -> 76.76 | AO7: 72000 | AP7: Last W/O 08/2023 (ESP Upgrade),Started up On 25/08/2023 | BJ7: =+IF(E7="SI",0,AK7*AM7/100) -> 1842.24 | CW7: KHALDA_WELL | CX7: =REPORTDATE-1 -> 46284 | CY7: =$CV$3&B7 -> 9ERZK-21 | CZ7: =J7 -> 128 | DA7: =K7 -> 170 | DB7: =F7 -> 24 | DC7: =IF(DB7=0,"SI",E7) -> ESP | DF7: =O7 -> 156 | DG7: =AA7 -> 0 | DH7: =AB7 -> 0 | DI7: =AC7 -> 0 | DJ7: =AD7 -> 0 | DK7: =AE7 -> 50 | DN7: =AF7 -> 50 | DO7: =AI7 -> 76.76 | DP7: =IF(H7="","",H7) | DQ7: =AN7/24*HOURS -> 76.76 | DR7: =I7 -> 6 | DS7: =IF(OR(E7="SI",B7="",E7="T&A"),"",VLOOKUP(B7,WELL_FIELD,2)) -> EAST | DY7: =IF(B7="","","KHALDA_WELL") -> KHALDA_WELL | DZ7: =REPORTDATE-1 -> 46284 | EA7: =B7 -> ERZK-21 | EB7: =J7 -> 128 | EC7: =K7 -> 170 | ED7: =F7 -> 24 | EE7: =IF(DB7=0,"SI",E7) -> ESP | EH7: =IF(H7="","",H7) | EI7: =AI7 -> 76.76 | EJ7: =V7 -> SN3600 | EK7: =G7 -> 0 | EN7: =AB7 -> 0 | EP7: =AC7 -> 0 | EQ7: =AE7 -> 50 | ET7: =AD7 -> 0 | EU7: =AF7 -> 50 | EW7: =W7 -> 0 | EX7: =X7 -> 0 | EY7: =Y7 -> 0 | EZ7: =Z7 -> 0 | FA7: =AP7 -> Last W/O 08/2023 (ESP Upgrade),Started up On 25/08/2023 | FB7: =IF(OR(E7="SI",B7="",E7="T&A"),"",VLOOKUP(B7,WELL_FIELD,2)) -> EAST
B8: ERZK-110 | C8: MULTIZONE | D8: ESP(SN2600) | E8: SI | F8: 0 | G8: =IF(OR(WSTATUS="T&A",DTCAUSE="PUMP OFF MODE",DTCAUSE="UNDER LOAD"),0,BOPD/24*(24-HOURS)) -> 69.3 | K8: 950 | M8: 180 | AH8: =IF(AG8="","",AE8/AG8*100) | AI8: =AN8/24*F8 -> 0 | AK8: 70 | AM8: 1 | AN8: =IF(BFPD=0,0,BFPD*(1-BSW/100)) -> 69.3 | AP8: S/D 14-07-2022 due to D.H.P Last W/O 02/2015 (RC). On 16/12/2019 Fully opened prod. CK | BJ8: =+IF(E8="SI",0,AK8*AM8/100) -> 0 | CW8: KHALDA_WELL | CX8: =REPORTDATE-1 -> 46284 | CY8: =$CV$3&B8 -> 9ERZK-110 | CZ8: =J8 -> 0 | DA8: =K8 -> 950 | DB8: =F8 -> 0 | DC8: =IF(DB8=0,"SI",E8) -> SI | DF8: =O8 -> 0 | DG8: =AA8 -> 0 | DH8: =AB8 -> 0 | DI8: =AC8 -> 0 | DJ8: =AD8 -> 0 | DK8: =AE8 -> 0 | DN8: =AF8 -> 0 | DO8: =AI8 -> 0 | DP8: =IF(H8="","",H8) | DQ8: =AN8/24*HOURS -> 0 | DR8: =I8 -> 0 | DS8: =IF(OR(E8="SI",B8="",E8="T&A"),"",VLOOKUP(B8,WELL_FIELD,2)) | DY8: =IF(B8="","","KHALDA_WELL") -> KHALDA_WELL | DZ8: =REPORTDATE-1 -> 46284 | EA8: =B8 -> ERZK-110 | EB8: =J8 -> 0 | EC8: =K8 -> 950 | ED8: =F8 -> 0 | EE8: =IF(DB8=0,"SI",E8) -> SI | EH8: =IF(H8="","",H8) | EI8: =AI8 -> 0 | EJ8: =V8 -> 0 | EK8: =G8 -> 69.3 | EN8: =AB8 -> 0 | EP8: =AC8 -> 0 | EQ8: =AE8 -> 0 | ET8: =AD8 -> 0 | EU8: =AF8 -> 0 | EW8: =W8 -> 0 | EX8: =X8 -> 0 | EY8: =Y8 -> 0 | EZ8: =Z8 -> 0 | FA8: =AP8 -> S/D 14-07-2022 due to D.H.P Last W/O 02/2015 (RC). On 16/12/2019 Fully opened prod. CK | FB8: =IF(OR(E8="SI",B8="",E8="T&A"),"",VLOOKUP(B8,WELL_FIELD,2))
B9: ERZK-111 | C9: MULTIZONE | D9: ESP(D800N) | E9: ESP | F9: 24 | G9: =IF(OR(WSTATUS="T&A",DTCAUSE="PUMP OFF MODE",DTCAUSE="UNDER LOAD"),0,BOPD/24*(24-HOURS)) -> 0 | I9: 5 | J9: Spool | K9: 140 | L9: 130 | M9: 0 | N9: OP | O9: 151 | P9: 46135 | Q9: 4560 | R9: 89 | S9: 1270 | U9: 5991 | V9: Borets 400-2200 | AE9: 42 | AF9: 56 | AG9: 44 | AH9: =IF(AG9="","",AE9/AG9*100) -> 95.454545 | AI9: =AN9/24*F9 -> 91.561 | AJ9: 46276 | AK9: 1501 | AM9: 93.9 | AN9: =IF(BFPD=0,0,BFPD*(1-BSW/100)) -> 91.561 | AO9: 66000 | AP9: Last W/O 02/2021 (RW-Pump upgrade),Perf & Reperf UBAH-200&210 / LBAH Start-up on 20-Feb-21 W/BORETS 400-2200 | BJ9: =+IF(E9="SI",0,AK9*AM9/100) -> 1409.439 | CW9: KHALDA_WELL | CX9: =REPORTDATE-1 -> 46284 | CY9: =$CV$3&B9 -> 9ERZK-111 | CZ9: =J9 -> Spool | DA9: =K9 -> 140 | DB9: =F9 -> 24 | DC9: =IF(DB9=0,"SI",E9) -> ESP | DF9: =O9 -> 151 | DG9: =AA9 -> 0 | DH9: =AB9 -> 0 | DI9: =AC9 -> 0 | DJ9: =AD9 -> 0 | DK9: =AE9 -> 42 | DN9: =AF9 -> 56 | DO9: =AI9 -> 91.561 | DP9: =IF(H9="","",H9) | DQ9: =AN9/24*HOURS -> 91.561 | DR9: =I9 -> 5 | DS9: =IF(OR(E9="SI",B9="",E9="T&A"),"",VLOOKUP(B9,WELL_FIELD,2)) -> EAST | DY9: =IF(B9="","","KHALDA_WELL") -> KHALDA_WELL | DZ9: =REPORTDATE-1 -> 46284 | EA9: =B9 -> ERZK-111 | EB9: =J9 -> Spool | EC9: =K9 -> 140 | ED9: =F9 -> 24 | EE9: =IF(DB9=0,"SI",E9) -> ESP | EH9: =IF(H9="","",H9) | EI9: =AI9 -> 91.561 | EJ9: =V9 -> Borets 400-2200 | EK9: =G9 -> 0 | EN9: =AB9 -> 0 | EP9: =AC9 -> 0 | EQ9: =AE9 -> 42 | ET9: =AD9 -> 0 | EU9: =AF9 -> 56 | EW9: =W9 -> 0 | EX9: =X9 -> 0 | EY9: =Y9 -> 0 | EZ9: =Z9 -> 0 | FA9: =AP9 -> Last W/O 02/2021 (RW-Pump upgrade),Perf & Reperf UBAH-200&210 / LBAH Start-up on 20-Feb-21 W/BORETS 400-2200 | FB9: =IF(OR(E9="SI",B9="",E9="T&A"),"",VLOOKUP(B9,WELL_FIELD,2)) -> EAST
B10: ERZK-127 | C10: LBAH | D10: ESP(SN2600) | E10: ESP | F10: 24 | G10: =IF(OR(WSTATUS="T&A",DTCAUSE="PUMP OFF MODE",DTCAUSE="UNDER LOAD"),0,BOPD/24*(24-HOURS)) -> 0 | I10: 1000 | J10: Spool | K10: 300 | L10: 300 | M10: 200 | N10: OP | O10: 170 | P10: 45229 | Q10: 2143 | R10: 100 | S10: 1878 | U10: 4023 | V10: SN3600 | AE10: 54 | AF10: 50 | AG10: 61.7 | AH10: =IF(AG10="","",AE10/AG10*100) -> 87.520259 | AI10: =AN10/24*F10 -> 57.596 | AJ10: 46227 | AK10: 2618 | AM10: 97.8 | AN10: =IF(BFPD=0,0,BFPD*(1-BSW/100)) -> 57.596 | AO10: 71000 | AP10: Last W/O 10/2021 TBG Replacement & Pump Upgrade, Started up 26/10/2021. | BJ10: =+IF(E10="SI",0,AK10*AM10/100) -> 2560.404 | CW10: KHALDA_WELL | CX10: =REPORTDATE-1 -> 46284 | CY10: =$CV$3&B10 -> 9ERZK-127 | CZ10: =J10 -> Spool | DA10: =K10 -> 300 | DB10: =F10 -> 24 | DC10: =IF(DB10=0,"SI",E10) -> ESP | DF10: =O10 -> 170 | DG10: =AA10 -> 0 | DH10: =AB10 -> 0 | DI10: =AC10 -> 0 | DJ10: =AD10 -> 0 | DK10: =AE10 -> 54 | DN10: =AF10 -> 50 | DO10: =AI10 -> 57.596 | DP10: =IF(H10="","",H10) | DQ10: =AN10/24*HOURS -> 57.596 | DR10: =I10 -> 1000 | DS10: =IF(OR(E10="SI",B10="",E10="T&A"),"",VLOOKUP(B10,WELL_FIELD,2)) -> EAST | DY10: =IF(B10="","","KHALDA_WELL") -> KHALDA_WELL | DZ10: =REPORTDATE-1 -> 46284 | EA10: =B10 -> ERZK-127 | EB10: =J10 -> Spool | EC10: =K10 -> 300 | ED10: =F10 -> 24 | EE10: =IF(DB10=0,"SI",E10) -> ESP | EH10: =IF(H10="","",H10) | EI10: =AI10 -> 57.596 | EJ10: =V10 -> SN3600 | EK10: =G10 -> 0 | EN10: =AB10 -> 0 | EP10: =AC10 -> 0 | EQ10: =AE10 -> 54 | ET10: =AD10 -> 0 | EU10: =AF10 -> 50 | EW10: =W10 -> 0 | EX10: =X10 -> 0 | EY10: =Y10 -> 0 | EZ10: =Z10 -> 0 | FA10: =AP10 -> Last W/O 10/2021 TBG Replacement & Pump Upgrade, Started up 26/10/2021. | FB10: =IF(OR(E10="SI",B10="",E10="T&A"),"",VLOOKUP(B10,WELL_FIELD,2)) -> EAST
B11: ERZK-129 | C11: L,BBAH | D11: ESP(GN2100) | E11: ESP | F11: 24 | G11: =IF(OR(WSTATUS="T&A",DTCAUSE="PUMP OFF MODE",DTCAUSE="UNDER LOAD"),0,BOPD/24*(24-HOURS)) -> 0 | I11: 0 | J11: Spool | K11: 210 | L11: 200 | M11: 0 | N11: OP | O11: 145 | P11: 46148 | Q11: Fluid level couldn’t be detected | U11: 6250 | V11: DN1150 | AE11: 26 | AF11: 45 | AG11: 24.4 | AH11: =IF(AG11="","",AE11/AG11*100) -> 106.55738 | AI11: =AN11/24*F11 -> 86.24 | AJ11: 46275 | AK11: 616 | AM11: 86 | AN11: =IF(BFPD=0,0,BFPD*(1-BSW/100)) -> 86.24 | AO11: 79000 | AP11: Last W/O 05/2025 (R/C), Started up 27/05/2025 | BJ11: =+IF(E11="SI",0,AK11*AM11/100) -> 529.76 | CW11: KHALDA_WELL | CX11: =REPORTDATE-1 -> 46284 | CY11: =$CV$3&B11 -> 9ERZK-129 | CZ11: =J11 -> Spool | DA11: =K11 -> 210 | DB11: =F11 -> 24 | DC11: =IF(DB11=0,"SI",E11) -> ESP | DF11: =O11 -> 145 | DG11: =AA11 -> 0 | DH11: =AB11 -> 0 | DI11: =AC11 -> 0 | DJ11: =AD11 -> 0 | DK11: =AE11 -> 26 | DN11: =AF11 -> 45 | DO11: =AI11 -> 86.24 | DP11: =IF(H11="","",H11) | DQ11: =AN11/24*HOURS -> 86.24 | DR11: =I11 -> 0 | DS11: =IF(OR(E11="SI",B11="",E11="T&A"),"",VLOOKUP(B11,WELL_FIELD,2)) -> EAST | DY11: =IF(B11="","","KHALDA_WELL") -> KHALDA_WELL | DZ11: =REPORTDATE-1 -> 46284 | EA11: =B11 -> ERZK-129 | EB11: =J11 -> Spool | EC11: =K11 -> 210 | ED11: =F11 -> 24 | EE11: =IF(DB11=0,"SI",E11) -> ESP | EH11: =IF(H11="","",H11) | EI11: =AI11 -> 86.24 | EJ11: =V11 -> DN1150 | EK11: =G11 -> 0 | EN11: =AB11 -> 0 | EP11: =AC11 -> 0 | EQ11: =AE11 -> 26 | ET11: =AD11 -> 0 | EU11: =AF11 -> 45 | EW11: =W11 -> 0 | EX11: =X11 -> 0 | EY11: =Y11 -> 0 | EZ11: =Z11 -> 0 | FA11: =AP11 -> Last W/O 05/2025 (R/C), Started up 27/05/2025 | FB11: =IF(OR(E11="SI",B11="",E11="T&A"),"",VLOOKUP(B11,WELL_FIELD,2)) -> EAST
B12: ERZK-130 | C12: BAH | D12: N.F | E12: ESP | F12: 24 | G12: =IF(OR(WSTATUS="T&A",DTCAUSE="PUMP OFF MODE",DTCAUSE="UNDER LOAD"),0,BOPD/24*(24-HOURS)) -> 0 | I12: 5 | J12: Spool | K12: 190 | L12: 170 | M12: 0 | N12: OP | O12: 126 | P12: 46135 | Q12: 4266 | R12: 83 | S12: 1255 | U12: 5885 | V12: WD650 | AE12: 16 | AF12: 50 | AG12: 30 | AH12: =IF(AG12="","",AE12/AG12*100) -> 53.333333 | AI12: =AN12/24*F12 -> 33.48 | AJ12: 46277 | AK12: 465 | AM12: 92.8 | AN12: =IF(BFPD=0,0,BFPD*(1-BSW/100)) -> 33.48 | AO12: 62000 | AP12: Started up to production 17-11-2025 after w/o pump down grade F/DN800 T/WD650 | BJ12: =+IF(E12="SI",0,AK12*AM12/100) -> 431.52 | CW12: KHALDA_WELL | CX12: =REPORTDATE-1 -> 46284 | CY12: =$CV$3&B12 -> 9ERZK-130 | CZ12: =J12 -> Spool | DA12: =K12 -> 190 | DB12: =F12 -> 24 | DC12: =IF(DB12=0,"SI",E12) -> ESP | DF12: =O12 -> 126 | DG12: =AA12 -> 0 | DH12: =AB12 -> 0 | DI12: =AC12 -> 0 | DJ12: =AD12 -> 0 | DK12: =AE12 -> 16 | DN12: =AF12 -> 50 | DO12: =AI12 -> 33.48 | DP12: =IF(H12="","",H12) | DQ12: =AN12/24*HOURS -> 33.48 | DR12: =I12 -> 5 | DS12: =IF(OR(E12="SI",B12="",E12="T&A"),"",VLOOKUP(B12,WELL_FIELD,2)) -> EAST | DY12: =IF(B12="","","KHALDA_WELL") -> KHALDA_WELL | DZ12: =REPORTDATE-1 -> 46284 | EA12: =B12 -> ERZK-130 | EB12: =J12 -> Spool | EC12: =K12 -> 190 | ED12: =F12 -> 24 | EE12: =IF(DB12=0,"SI",E12) -> ESP | EH12: =IF(H12="","",H12) | EI12: =AI12 -> 33.48 | EJ12: =V12 -> WD650 | EK12: =G12 -> 0 | EN12: =AB12 -> 0 | EP12: =AC12 -> 0 | EQ12: =AE12 -> 16 | ET12: =AD12 -> 0 | EU12: =AF12 -> 50 | EW12: =W12 -> 0 | EX12: =X12 -> 0 | EY12: =Y12 -> 0 | EZ12: =Z12 -> 0 | FA12: =AP12 -> Started up to production 17-11-2025 after w/o pump down grade F/DN800 T/WD650 | FB12: =IF(OR(E12="SI",B12="",E12="T&A"),"",VLOOKUP(B12,WELL_FIELD,2)) -> EAST
B13: ERZK-153 | C13: U/L-BAH | E13: ESP | F13: 24 | G13: =IF(OR(WSTATUS="T&A",DTCAUSE="PUMP OFF MODE",DTCAUSE="UNDER LOAD"),0,BOPD/24*(24-HOURS)) -> 0 | I13: 0 | J13: 128 | K13: 180 | L13: 120 | M13: 0 | N13: OP | O13: 129 | P13: 46148 | Q13: 4342.81 | R13: 88 | S13: 1076 | U13: 5570 | V13: FLEX-10 | AE13: 26 | AF13: 50 | AG13: 34 | AH13: =IF(AG13="","",AE13/AG13*100) -> 76.470588 | AI13: =AN13/24*F13 -> 33.792 | AJ13: 46227 | AK13: 528 | AM13: 93.6 | AN13: =IF(BFPD=0,0,BFPD*(1-BSW/100)) -> 33.792 | AO13: 65000 | AP13: Sarted up 31-01-2025 Last W/O 01/2025 (R/W) | BJ13: =+IF(E13="SI",0,AK13*AM13/100) -> 494.208 | CW13: KHALDA_WELL | CX13: =REPORTDATE-1 -> 46284 | CY13: =$CV$3&B13 -> 9ERZK-153 | CZ13: =J13 -> 128 | DA13: =K13 -> 180 | DB13: =F13 -> 24 | DC13: =IF(DB13=0,"SI",E13) -> ESP | DF13: =O13 -> 129 | DG13: =AA13 -> 0 | DH13: =AB13 -> 0 | DI13: =AC13 -> 0 | DJ13: =AD13 -> 0 | DK13: =AE13 -> 26 | DN13: =AF13 -> 50 | DO13: =AI13 -> 33.792 | DP13: =IF(H13="","",H13) | DQ13: =AN13/24*HOURS -> 33.792 | DR13: =I13 -> 0 | DS13: =IF(OR(E13="SI",B13="",E13="T&A"),"",VLOOKUP(B13,WELL_FIELD,2)) -> EAST | DY13: =IF(B13="","","KHALDA_WELL") -> KHALDA_WELL | DZ13: =REPORTDATE-1 -> 46284 | EA13: =B13 -> ERZK-153 | EB13: =J13 -> 128 | EC13: =K13 -> 180 | ED13: =F13 -> 24 | EE13: =IF(DB13=0,"SI",E13) -> ESP | EH13: =IF(H13="","",H13) | EI13: =AI13 -> 33.792 | EJ13: =V13 -> FLEX-10 | EK13: =G13 -> 0 | EN13: =AB13 -> 0 | EP13: =AC13 -> 0 | EQ13: =AE13 -> 26 | ET13: =AD13 -> 0 | EU13: =AF13 -> 50 | EW13: =W13 -> 0 | EX13: =X13 -> 0 | EY13: =Y13 -> 0 | EZ13: =Z13 -> 0 | FA13: =AP13 -> Sarted up 31-01-2025 Last W/O 01/2025 (R/W) | FB13: =IF(OR(E13="SI",B13="",E13="T&A"),"",VLOOKUP(B13,WELL_FIELD,2)) -> EAST
B14: ERZK-163 | C14: UBAH | E14: ESP | F14: 24 | G14: =IF(OR(WSTATUS="T&A",DTCAUSE="PUMP OFF MODE",DTCAUSE="UNDER LOAD"),0,BOPD/24*(24-HOURS)) -> 0 | I14: 3 | J14: 128 | K14: 140 | L14: 130 | M14: 0 | N14: OP | O14: 149 | U14: 5500 | V14: 400-1050 | AE14: 23 | AF14: 55 | AG14: 24.5 | AH14: =IF(AG14="","",AE14/AG14*100) -> 93.877551 | AI14: =AN14/24*F14 -> 80.5225 | AJ14: 46285 | AK14: 1039 | AM14: 92.25 | AN14: =IF(BFPD=0,0,BFPD*(1-BSW/100)) -> 80.5225 | AO14: 70000 | AP14: Started up 23/6/2024 Last W/O 06/2024 (Replaced SRP W/ ESP) | BJ14: =+IF(E14="SI",0,AK14*AM14/100) -> 958.4775 | CW14: KHALDA_WELL | CX14: =REPORTDATE-1 -> 46284 | CY14: =$CV$3&B14 -> 9ERZK-163 | CZ14: =J14 -> 128 | DA14: =K14 -> 140 | DB14: =F14 -> 24 | DC14: =IF(DB14=0,"SI",E14) -> ESP | DF14: =O14 -> 149 | DG14: =AA14 -> 0 | DH14: =AB14 -> 0 | DI14: =AC14 -> 0 | DJ14: =AD14 -> 0 | DK14: =AE14 -> 23 | DN14: =AF14 -> 55 | DO14: =AI14 -> 80.5225 | DP14: =IF(H14="","",H14) | DQ14: =AN14/24*HOURS -> 80.5225 | DR14: =I14 -> 3 | DS14: =IF(OR(E14="SI",B14="",E14="T&A"),"",VLOOKUP(B14,WELL_FIELD,2)) -> EAST | DY14: =IF(B14="","","KHALDA_WELL") -> KHALDA_WELL | DZ14: =REPORTDATE-1 -> 46284 | EA14: =B14 -> ERZK-163 | EB14: =J14 -> 128 | EC14: =K14 -> 140 | ED14: =F14 -> 24 | EE14: =IF(DB14=0,"SI",E14) -> ESP | EH14: =IF(H14="","",H14) | EI14: =AI14 -> 80.5225 | EJ14: =V14 -> 400-1050 | EK14: =G14 -> 0 | EN14: =AB14 -> 0 | EP14: =AC14 -> 0 | EQ14: =AE14 -> 23 | ET14: =AD14 -> 0 | EU14: =AF14 -> 55 | EW14: =W14 -> 0 | EX14: =X14 -> 0 | EY14: =Y14 -> 0 | EZ14: =Z14 -> 0 | FA14: =AP14 -> Started up 23/6/2024 Last W/O 06/2024 (Replaced SRP W/ ESP) | FB14: =IF(OR(E14="SI",B14="",E14="T&A"),"",VLOOKUP(B14,WELL_FIELD,2)) -> EAST
B15: ERZK-180 | C15: APOLLONIA | E15: SI | F15: 0 | G15: =IF(OR(WSTATUS="T&A",DTCAUSE="PUMP OFF MODE",DTCAUSE="UNDER LOAD"),0,BOPD/24*(24-HOURS)) -> 570 | I15: 6000 | J15: Spool | K15: 170 | L15: 150 | N15: OP | O15: 121 | P15: 45967 | Q15: 2561 | R15: 100 | S15: 1082 | U15: 3665 | V15: 2.25 | W15: 100 | X15: 569 | Y15: 98 | Z15: 80 | AA15: C-912 | AB15: 6.8 | AC15: 169 | AD15: 950 | AH15: =IF(AG15="","",AE15/AG15*100) | AI15: =AN15/24*F15 -> 0 | AJ15: 45968 | AK15: 570 | AN15: =IF(BFPD=0,0,BFPD*(1-BSW/100)) -> 570 | AO15: 62000 | AP15: Rerun on 18-01-2025, was S/I on 25/06/2024- due to uneconomic oil production. | BJ15: =+IF(E15="SI",0,AK15*AM15/100) -> 0 | CW15: KHALDA_WELL | CX15: =REPORTDATE-1 -> 46284 | CY15: =$CV$3&B15 -> 9ERZK-180 | CZ15: =J15 -> Spool | DA15: =K15 -> 170 | DB15: =F15 -> 0 | DC15: =IF(DB15=0,"SI",E15) -> SI | DF15: =O15 -> 121 | DG15: =AA15 -> C-912 | DH15: =AB15 -> 6.8 | DI15: =AC15 -> 169 | DJ15: =AD15 -> 950 | DK15: =AE15 -> 0 | DN15: =AF15 -> 0 | DO15: =AI15 -> 0 | DP15: =IF(H15="","",H15) | DQ15: =AN15/24*HOURS -> 0 | DR15: =I15 -> 6000 | DS15: =IF(OR(E15="SI",B15="",E15="T&A"),"",VLOOKUP(B15,WELL_FIELD,2)) | DY15: =IF(B15="","","KHALDA_WELL") -> KHALDA_WELL | DZ15: =REPORTDATE-1 -> 46284 | EA15: =B15 -> ERZK-180 | EB15: =J15 -> Spool | EC15: =K15 -> 170 | ED15: =F15 -> 0 | EE15: =IF(DB15=0,"SI",E15) -> SI | EH15: =IF(H15="","",H15) | EI15: =AI15 -> 0 | EJ15: =V15 -> 2.25 | EK15: =G15 -> 570 | EN15: =AB15 -> 6.8 | EP15: =AC15 -> 169 | EQ15: =AE15 -> 0 | ET15: =AD15 -> 950 | EU15: =AF15 -> 0 | EW15: =W15 -> 100 | EX15: =X15 -> 569 | EY15: =Y15 -> 98 | EZ15: =Z15 -> 80 | FA15: =AP15 -> Rerun on 18-01-2025, was S/I on 25/06/2024- due to uneconomic oil production. | FB15: =IF(OR(E15="SI",B15="",E15="T&A"),"",VLOOKUP(B15,WELL_FIELD,2))
B16: ERZK-199 | C16: UBAH/ARG | E16: ESP | F16: 24 | G16: =IF(OR(WSTATUS="T&A",DTCAUSE="PUMP OFF MODE",DTCAUSE="UNDER LOAD"),0,BOPD/24*(24-HOURS)) -> 0 | I16: 13 | J16: 14 | K16: 410 | L16: 160 | M16: 0 | N16: OP | O16: 131 | P16: 46113 | Q16: 3676.06 | R16: 33 | S16: 572 | U16: 5474 | V16: 400-1050 | AE16: 18 | AF16: 56 | AG16: 28 | AH16: =IF(AG16="","",AE16/AG16*100) -> 64.285714 | AI16: =AN16/24*F16 -> 239.475 | AJ16: 46279 | AK16: 515 | AM16: 53.5 | AN16: =IF(BFPD=0,0,BFPD*(1-BSW/100)) -> 239.475 | AO16: 56000 | AP16: Last W/O 03/2024 (R/C), Started up 20/03/2024 | BJ16: =+IF(E16="SI",0,AK16*AM16/100) -> 275.525 | CW16: KHALDA_WELL | CX16: =REPORTDATE-1 -> 46284 | CY16: =$CV$3&B16 -> 9ERZK-199 | CZ16: =J16 -> 14 | DA16: =K16 -> 410 | DB16: =F16 -> 24 | DC16: =IF(DB16=0,"SI",E16) -> ESP | DF16: =O16 -> 131 | DG16: =AA16 -> 0 | DH16: =AB16 -> 0 | DI16: =AC16 -> 0 | DJ16: =AD16 -> 0 | DK16: =AE16 -> 18 | DN16: =AF16 -> 56 | DO16: =AI16 -> 239.475 | DP16: =IF(H16="","",H16) | DQ16: =AN16/24*HOURS -> 239.475 | DR16: =I16 -> 13 | DS16: =IF(OR(E16="SI",B16="",E16="T&A"),"",VLOOKUP(B16,WELL_FIELD,2)) -> EAST | DY16: =IF(B16="","","KHALDA_WELL") -> KHALDA_WELL | DZ16: =REPORTDATE-1 -> 46284 | EA16: =B16 -> ERZK-199 | EB16: =J16 -> 14 | EC16: =K16 -> 410 | ED16: =F16 -> 24 | EE16: =IF(DB16=0,"SI",E16) -> ESP | EH16: =IF(H16="","",H16) | EI16: =AI16 -> 239.475 | EJ16: =V16 -> 400-1050 | EK16: =G16 -> 0 | EN16: =AB16 -> 0 | EP16: =AC16 -> 0 | EQ16: =AE16 -> 18 | ET16: =AD16 -> 0 | EU16: =AF16 -> 56 | EW16: =W16 -> 0 | EX16: =X16 -> 0 | EY16: =Y16 -> 0 | EZ16: =Z16 -> 0 | FA16: =AP16 -> Last W/O 03/2024 (R/C), Started up 20/03/2024 | FB16: =IF(OR(E16="SI",B16="",E16="T&A"),"",VLOOKUP(B16,WELL_FIELD,2)) -> EAST
B17: ERZK-202 | C17: ARG | E17: SI | F17: 0 | G17: =IF(OR(WSTATUS="T&A",DTCAUSE="PUMP OFF MODE",DTCAUSE="UNDER LOAD"),0,BOPD/24*(24-HOURS)) -> 0 | I17: 5 | J17: Spool | K17: 60 | L17: 140 | M17: 10 | N17: OP | O17: 109 | P17: 45921 | R17: 100 | S17: 3377 | T17: 1601 | U17: 5378 | V17: D1150N | AI17: =AN17/24*F17 -> 0 | AN17: =IF(BFPD=0,0,BFPD*(1-BSW/100)) -> 0 | AP17: S/D on 08-08-2024 due to high Tm & gas lock to save DH Pump Last W/O 09/2022 (Isolate U&LBAH and R/C acidize ARG-DOL.), Started up to production 29-9-2022 after W/O | BJ17: =+IF(E17="SI",0,AK17*AM17/100) -> 0 | CW17: KHALDA_WELL | CX17: =REPORTDATE-1 -> 46284 | CY17: =$CV$3&B17 -> 9ERZK-202 | CZ17: =J17 -> Spool | DA17: =K17 -> 60 | DB17: =F17 -> 0 | DC17: =IF(DB17=0,"SI",E17) -> SI | DF17: =O17 -> 109 | DG17: =AA17 -> 0 | DH17: =AB17 -> 0 | DI17: =AC17 -> 0 | DJ17: =AD17 -> 0 | DK17: =AE17 -> 0 | DN17: =AF17 -> 0 | DO17: =AI17 -> 0 | DP17: =IF(H17="","",H17) | DQ17: =AN17/24*HOURS -> 0 | DR17: =I17 -> 5 | DS17: =IF(OR(E17="SI",B17="",E17="T&A"),"",VLOOKUP(B17,WELL_FIELD,2)) | DY17: =IF(B17="","","KHALDA_WELL") -> KHALDA_WELL | DZ17: =REPORTDATE-1 -> 46284 | EA17: =B17 -> ERZK-202 | EB17: =J17 -> Spool | EC17: =K17 -> 60 | ED17: =F17 -> 0 | EE17: =IF(DB17=0,"SI",E17) -> SI | EH17: =IF(H17="","",H17) | EI17: =AI17 -> 0 | EJ17: =V17 -> D1150N | EK17: =G17 -> 0 | EN17: =AB17 -> 0 | EP17: =AC17 -> 0 | EQ17: =AE17 -> 0 | ET17: =AD17 -> 0 | EU17: =AF17 -> 0 | EW17: =W17 -> 0 | EX17: =X17 -> 0 | EY17: =Y17 -> 0 | EZ17: =Z17 -> 0 | FA17: =AP17 -> S/D on 08-08-2024 due to high Tm & gas lock to save DH Pump Last W/O 09/2022 (Isolate U&LBAH and R/C acidize ARG-DOL.), Started up to production 29-9-2022 after W/O | FB17: =IF(OR(E17="SI",B17="",E17="T&A"),"",VLOOKUP(B17,WELL_FIELD,2))
B18: AKIK-NE01 | C18: ALMDOL | D18: NF | E18: NF | F18: 24 | G18: =IF(OR(WSTATUS="T&A",DTCAUSE="PUMP OFF MODE",DTCAUSE="UNDER LOAD"),0,BOPD/24*(24-HOURS)) -> 0 | I18: 0 | J18: 36 | K18: 1140 | L18: 100 | N18: CL | O18: 127 | S18: N.F | AH18: =IF(AG18="","",AE18/AG18*100) | AI18: =AN18/24*F18 -> 243.25 | AJ18: 46285 | AK18: 1390 | AL18: 1.991 | AM18: 82.5 | AN18: =IF(BFPD=0,0,BFPD*(1-BSW/100)) -> 243.25 | AO18: 96000 | AP18: Last W/O 08/2026, Isolated AEB, Perf. ALMDOL | BJ18: =+IF(E18="SI",0,AK18*AM18/100) -> 1146.75 | CW18: KHALDA_WELL | CX18: =REPORTDATE-1 -> 46284 | CY18: =$CV$3&B18 -> 9AKIK-NE01 | CZ18: =J18 -> 36 | DA18: =K18 -> 1140 | DB18: =F18 -> 24 | DC18: =IF(DB18=0,"SI",E18) -> NF | DF18: =O18 -> 127 | DG18: =AA18 -> 0 | DH18: =AB18 -> 0 | DI18: =AC18 -> 0 | DJ18: =AD18 -> 0 | DK18: =AE18 -> 0 | DN18: =AF18 -> 0 | DO18: =AI18 -> 243.25 | DP18: =IF(H18="","",H18) | DQ18: =AN18/24*HOURS -> 243.25 | DR18: =I18 -> 0 | DS18: =IF(OR(E18="SI",B18="",E18="T&A"),"",VLOOKUP(B18,WELL_FIELD,2)) -> AKIK-NE | DY18: =IF(B18="","","KHALDA_WELL") -> KHALDA_WELL | DZ18: =REPORTDATE-1 -> 46284 | EA18: =B18 -> AKIK-NE01 | EB18: =J18 -> 36 | EC18: =K18 -> 1140 | ED18: =F18 -> 24 | EE18: =IF(DB18=0,"SI",E18) -> NF | EH18: =IF(H18="","",H18) | EI18: =AI18 -> 243.25 | EJ18: =V18 -> 0 | EK18: =G18 -> 0 | EN18: =AB18 -> 0 | EP18: =AC18 -> 0 | EQ18: =AE18 -> 0 | ET18: =AD18 -> 0 | EU18: =AF18 -> 0 | EW18: =W18 -> 0 | EX18: =X18 -> 0 | EY18: =Y18 -> 0 | EZ18: =Z18 -> 0 | FA18: =AP18 -> Last W/O 08/2026, Isolated AEB, Perf. ALMDOL | FB18: =IF(OR(E18="SI",B18="",E18="T&A"),"",VLOOKUP(B18,WELL_FIELD,2)) -> AKIK-NE
B19: TANZ-02 | C19: ALMDOL | E19: SI | F19: 0 | G19: =IF(OR(WSTATUS="T&A",DTCAUSE="PUMP OFF MODE",DTCAUSE="UNDER LOAD"),0,BOPD/24*(24-HOURS)) -> 112.52 | M19: 1080 | N19: OP | O19: 62 | U19: 5885 | V19: 538-1500 | AG19: 51 | AH19: =IF(AG19="","",AE19/AG19*100) -> 0 | AI19: =AN19/24*F19 -> 0 | AJ19: 45809 | AK19: 116 | AM19: 3 | AN19: =IF(BFPD=0,0,BFPD*(1-BSW/100)) -> 112.52 | AP19: On 23-03-2025 bled off well through CSG to MTU S/D On 08-02-2024 due to uneconomic oil production Started up 15-12-2022 via EXPRO EPF, | BJ19: =+IF(E19="SI",0,AK19*AM19/100) -> 0 | CW19: KHALDA_WELL | CX19: =REPORTDATE-1 -> 46284 | CY19: =$CV$3&B19 -> 9TANZ-02 | CZ19: =J19 -> 0 | DA19: =K19 -> 0 | DB19: =F19 -> 0 | DC19: =IF(DB19=0,"SI",E19) -> SI | DF19: =O19 -> 62 | DG19: =AA19 -> 0 | DH19: =AB19 -> 0 | DI19: =AC19 -> 0 | DJ19: =AD19 -> 0 | DK19: =AE19 -> 0 | DN19: =AF19 -> 0 | DO19: =AI19 -> 0 | DP19: =IF(H19="","",H19) | DQ19: =AN19/24*HOURS -> 0 | DR19: =I19 -> 0 | DS19: =IF(OR(E19="SI",B19="",E19="T&A"),"",VLOOKUP(B19,WELL_FIELD,2)) | DY19: =IF(B19="","","KHALDA_WELL") -> KHALDA_WELL | DZ19: =REPORTDATE-1 -> 46284 | EA19: =B19 -> TANZ-02 | EB19: =J19 -> 0 | EC19: =K19 -> 0 | ED19: =F19 -> 0 | EE19: =IF(DB19=0,"SI",E19) -> SI | EH19: =IF(H19="","",H19) | EI19: =AI19 -> 0 | EJ19: =V19 -> 538-1500 | EK19: =G19 -> 112.52 | EN19: =AB19 -> 0 | EP19: =AC19 -> 0 | EQ19: =AE19 -> 0 | ET19: =AD19 -> 0 | EU19: =AF19 -> 0 | EW19: =W19 -> 0 | EX19: =X19 -> 0 | EY19: =Y19 -> 0 | EZ19: =Z19 -> 0 | FA19: =AP19 -> On 23-03-2025 bled off well through CSG to MTU S/D On 08-02-2024 due to uneconomic oil production Started up 15-12-2022 via EXPRO EPF, | FB19: =IF(OR(E19="SI",B19="",E19="T&A"),"",VLOOKUP(B19,WELL_FIELD,2))
B20: LADICE-01 | C20: LBAH | E20: ESP | F20: 24 | G20: =IF(OR(WSTATUS="T&A",DTCAUSE="PUMP OFF MODE",DTCAUSE="UNDER LOAD"),0,BOPD/24*(24-HOURS)) -> 0 | I20: 0 | J20: 128 | K20: 50 | L20: 50 | M20: 0 | N20: OP | O20: 153 | U20: 6897 | V20: FLEX-10 | AE20: 27 | AF20: 50 | AG20: 30 | AH20: =IF(AG20="","",AE20/AG20*100) -> 90 | AI20: =AN20/24*F20 -> 122.06744 | AJ20: 46284 | AK20: =814*0.92 -> 748.88 | AM20: 83.7 | AN20: =IF(BFPD=0,0,BFPD*(1-BSW/100)) -> 122.06744 | AO20: 86000 | AP20: W.C F/ collected WH samples Last W/O 06/2026 (ESPR Replaced B400-1050 W/Flex10), Started-up 22/06/2026 | BJ20: =+IF(E20="SI",0,AK20*AM20/100) -> 626.81256 | CW20: KHALDA_WELL | CX20: =REPORTDATE-1 -> 46284 | CY20: =$CV$3&B20 -> 9LADICE-01 | CZ20: =J20 -> 128 | DA20: =K20 -> 50 | DB20: =F20 -> 24 | DC20: =IF(DB20=0,"SI",E20) -> ESP | DF20: =O20 -> 153 | DG20: =AA20 -> 0 | DH20: =AB20 -> 0 | DI20: =AC20 -> 0 | DJ20: =AD20 -> 0 | DK20: =AE20 -> 27 | DN20: =AF20 -> 50 | DO20: =AI20 -> 122.06744 | DP20: =IF(H20="","",H20) | DQ20: =AN20/24*HOURS -> 122.06744 | DR20: =I20 -> 0 | DS20: =IF(OR(E20="SI",B20="",E20="T&A"),"",VLOOKUP(B20,WELL_FIELD,2)) -> NWRZK | DY20: =IF(B20="","","KHALDA_WELL") -> KHALDA_WELL | DZ20: =REPORTDATE-1 -> 46284 | EA20: =B20 -> LADICE-01 | EB20: =J20 -> 128 | EC20: =K20 -> 50 | ED20: =F20 -> 24 | EE20: =IF(DB20=0,"SI",E20) -> ESP | EH20: =IF(H20="","",H20) | EI20: =AI20 -> 122.06744 | EJ20: =V20 -> FLEX-10 | EK20: =G20 -> 0 | EN20: =AB20 -> 0 | EP20: =AC20 -> 0 | EQ20: =AE20 -> 27 | ET20: =AD20 -> 0 | EU20: =AF20 -> 50 | EW20: =W20 -> 0 | EX20: =X20 -> 0 | EY20: =Y20 -> 0 | EZ20: =Z20 -> 0 | FA20: =AP20 -> W.C F/ collected WH samples Last W/O 06/2026 (ESPR Replaced B400-1050 W/Flex10), Started-up 22/06/2026 | FB20: =IF(OR(E20="SI",B20="",E20="T&A"),"",VLOOKUP(B20,WELL_FIELD,2)) -> NWRZK
